Workbook

Sheet Calculator
A1: REMINDER: CUT & PASTE WILL CORRUPT FORMULAS ALWAYS USE COPY & PASTE | J1: Please use calculator to convert Drinks to Standard Drinking Units
E3: Input Subject ID and Sex | K3: Input date below | X3: Days -1 to -90 prior ICF:
A4: Staff Initials (calculation) | C4: RC | E4: Subject ID | H4: 1 | K4: Date of Screening | O4: 45925 | X4: Days between ICF and RAND: | AC4: =O5-O4 -> -45925
E5: Study Visit Name | H5: Screening Visit | Q5: =O4+45 -> 45970
AR6: Day of the week Pattern Chart 1 | AZ6: Day of the week Pattern Chart 2
E7: Beverage type #1 | H7: Beverage type #2 | K7: Beverage type #3 | N7: Beverage type #4 | Q7: Beverage type #5 | AR7: 2 | AS7: 3 | AT7: 4 | AU7: 5 | AV7: 6 | AW7: 7 | AX7: 1 | AZ7: 2 | BA7: 3 | BB7: 4 | BC7: 5 | BD7: 6 | BE7: 7 | BF7: 1 | BI7: Check for Missing data
A8: Drinking Day | B8: Day | C8: Date | D8: Pattern P1 A BLANK | E8: # of drinks | F8: # of oz per drink | G8: Conc. Of ETOH (ABV) | H8: # of drinks | I8: # of oz per drink | J8: Conc. Of ETOH (ABV) | K8: # of drinks | L8: # of oz per drink | M8: Conc. Of ETOH (ABV) | N8: # of drinks | O8: # of oz per drink | P8: Conc. Of ETOH (ABV) | Q8: # of drinks | R8: # of oz per drink | S8: Conc. Of ETOH (ABV) | T8: Total SDUs | U8: Do SDUs exceed 40 for this day? | V8: Confirm Values >40 with initials | X8: Drinking Day | Z8: Count drinking days in each 8-week period | AA8: Check for any period of 8 weeks abstinince | AB8: Determination if 8 weeks abstinence exists in time period | AE8: Average drinks per day in screening | AF8: =T104/X104 -> #DIV/0! | AH8: =CONCATENATE("The subject has consumed an average of ",AF8," drinks per day in the 90 days prior to consent") -> #DIV/0! | AL8: P1 Value | AM8: P2 Value | AN8: If P1 is True = day of week | AO8: If P2 is True = day of week | AQ8: Coded Day of week | AR8: P1 MON | AS8: P1 TUES | AT8: P1 WED | AU8: P1 THR | AV8: P1 FRI | AW8: P1 SAT | AX8: P1 SUN | AZ8: P2 MON | BA8: P2 TUES | BB8: P2 WED | BC8: P2 THR | BD8: P2 FRI | BE8: P2 SAT | BF8: P2 SUN | BI8: BEV1 | BJ8: BEV2 | BK8: BEV3 | BL8: BEV4 | BM8: BEV5 | BN8: Valid data for day (=1) no valid data (=0) | BQ8: Text Strings
A9: -90 | B9: =B10-1 -> 45835 | C9: =C10-1 -> 45835 | D9: A | T9: =IF(BN9=0,"M",IF(D9="p1",AL9,IF(D9="p2",AM9,IF(D9="A",0,((E9*F9)*G9/0.6)+((H9*I9)*J9/0.6)+((K9*L9)*M9/0.6)+((N9*O9)*P9/0.6)+((Q9*R9)*S9/0.6))))) -> 0 | U9: =IF(T9="M", "M", IF(T9>40, "YES", "NO")) -> NO | X9: =IF(T9="M",0,IF(T9=0,0,IF(T9>0,1,0))) -> 0 | AL9: =IF(AN9=1,AX9,IF(AN9=2,AR9,IF(AN9=3,AS9,IF(AN9=4,AT9,IF(AN9=5,AU9,IF(AN9=6,AV9,IF(AN9=7,AW9))))))) -> FALSE | AM9: =IF(AO9=1,BF9,IF(AO9=2,AZ9,IF(AO9=3,BA9,IF(AO9=4,BB9,IF(AO9=5,BC9,IF(AO9=6,BD9,IF(AO9=7,BE9))))))) -> FALSE | AN9: =IF(D9="p1",AQ9,"no") -> no | AO9: =IF(D9="p2",AQ9,"no") -> no | AQ9: =WEEKDAY(C9) -> 6 | AR9: ='P1 Chart'!Q4 -> M | AS9: ='P1 Chart'!Q5 -> M | AT9: ='P1 Chart'!Q6 -> 0.70833333 | AU9: ='P1 Chart'!Q7 -> M | AV9: ='P1 Chart'!Q8 -> M | AW9: ='P1 Chart'!Q9 -> 0.70833333 | AX9: ='P1 Chart'!Q10 -> M | AZ9: ='P1 Chart'!Q17 -> 0 | BA9: ='P1 Chart'!Q18 -> 0 | BB9: ='P1 Chart'!Q19 -> 0 | BC9: ='P1 Chart'!Q20 -> 0 | BD9: ='P1 Chart'!Q21 -> 0 | BE9: ='P1 Chart'!Q22 -> 0 | BF9: ='P1 Chart'!Q23 -> 0 | BI9: =IF(OR(E9="",F9="",G9=""),"M",1) -> M | BJ9: =IF(OR(H9="",I9="",J9=""),"M",1) -> M | BK9: =IF(OR(K9="",L9="",M9=""),"M",1) -> M | BL9: =IF(OR(N9="",O9="",P9=""),"M",1) -> M | BM9: =IF(OR(Q9="",R9="",S9=""),"M",1) -> M | BN9: =IF(AND(BI9="M",BJ9="M",BK9="M",BL9="M",BM9="M",D9=""),0,1) -> 1 | BO9: =SUM(BN9:BN98) -> 6 | BQ9: =IF(BO9=28,BQ19,BQ13) -> There are 84 days of missing drinking data in 90-day screening assessment period. Missing Baseline screening data must be collected prior to randomization.
A10: -89 | B10: =B11-1 -> 45836 | C10: =C11-1 -> 45836 | D10: A | T10: =IF(BN10=0,"M",IF(D10="p1",AL10,IF(D10="p2",AM10,IF(D10="A",0,((E10*F10)*G10/0.6)+((H10*I10)*J10/0.6)+((K10*L10)*M10/0.6)+((N10*O10)*P10/0.6)+((Q10*R10)*S10/0.6))))) -> 0 | U10: =IF(T10="M", "M", IF(T10>40, "YES", "NO")) -> NO | X10: =IF(T10="M",0,IF(T10=0,0,IF(T10>0,1,0))) -> 0 | AL10: =IF(AN10=1,AX10,IF(AN10=2,AR10,IF(AN10=3,AS10,IF(AN10=4,AT10,IF(AN10=5,AU10,IF(AN10=6,AV10,IF(AN10=7,AW10))))))) -> FALSE | AM10: =IF(AO10=1,BF10,IF(AO10=2,AZ10,IF(AO10=3,BA10,IF(AO10=4,BB10,IF(AO10=5,BC10,IF(AO10=6,BD10,IF(AO10=7,BE10))))))) -> FALSE | AN10: =IF(D10="p1",AQ10,"no") -> no | AO10: =IF(D10="p2",AQ10,"no") -> no | AQ10: =WEEKDAY(C10) -> 7 | AR10: =AR9 -> M | AS10: =AS9 -> M | AT10: =AT9 -> 0.70833333 | AU10: =AU9 -> M | AV10: =AV9 -> M | AW10: =AW9 -> 0.70833333 | AX10: =AX9 -> M | AZ10: =AZ9 -> 0 | BA10: =BA9 -> 0 | BB10: =BB9 -> 0 | BC10: =BC9 -> 0 | BD10: =BD9 -> 0 | BE10: =BE9 -> 0 | BF10: =BF9 -> 0 | BI10: =IF(OR(E10="",F10="",G10=""),"M",1) -> M | BJ10: =IF(OR(H10="",I10="",J10=""),"M",1) -> M | BK10: =IF(OR(K10="",L10="",M10=""),"M",1) -> M | BL10: =IF(OR(N10="",O10="",P10=""),"M",1) -> M | BM10: =IF(OR(Q10="",R10="",S10=""),"M",1) -> M | BN10: =IF(AND(BI10="M",BJ10="M",BK10="M",BL10="M",BM10="M",D10=""),0,1) -> 1 | BO10: 90
A11: -88 | B11: =B12-1 -> 45837 | C11: =C12-1 -> 45837 | D11: A | T11: =IF(BN11=0,"M",IF(D11="p1",AL11,IF(D11="p2",AM11,IF(D11="A",0,((E11*F11)*G11/0.6)+((H11*I11)*J11/0.6)+((K11*L11)*M11/0.6)+((N11*O11)*P11/0.6)+((Q11*R11)*S11/0.6))))) -> 0 | U11: =IF(T11="M", "M", IF(T11>40, "YES", "NO")) -> NO | X11: =IF(T11="M",0,IF(T11=0,0,IF(T11>0,1,0))) -> 0 | AL11: =IF(AN11=1,AX11,IF(AN11=2,AR11,IF(AN11=3,AS11,IF(AN11=4,AT11,IF(AN11=5,AU11,IF(AN11=6,AV11,IF(AN11=7,AW11))))))) -> FALSE | AM11: =IF(AO11=1,BF11,IF(AO11=2,AZ11,IF(AO11=3,BA11,IF(AO11=4,BB11,IF(AO11=5,BC11,IF(AO11=6,BD11,IF(AO11=7,BE11))))))) -> FALSE | AN11: =IF(D11="p1",AQ11,"no") -> no | AO11: =IF(D11="p2",AQ11,"no") -> no | AQ11: =WEEKDAY(C11) -> 1 | AR11: =AR10 -> M | AS11: =AS10 -> M | AT11: =AT10 -> 0.70833333 | AU11: =AU10 -> M | AV11: =AV10 -> M | AW11: =AW10 -> 0.70833333 | AX11: =AX10 -> M | AZ11: =AZ10 -> 0 | BA11: =BA10 -> 0 | BB11: =BB10 -> 0 | BC11: =BC10 -> 0 | BD11: =BD10 -> 0 | BE11: =BE10 -> 0 | BF11: =BF10 -> 0 | BI11: =IF(OR(E11="",F11="",G11=""),"M",1) -> M | BJ11: =IF(OR(H11="",I11="",J11=""),"M",1) -> M | BK11: =IF(OR(K11="",L11="",M11=""),"M",1) -> M | BL11: =IF(OR(N11="",O11="",P11=""),"M",1) -> M | BM11: =IF(OR(Q11="",R11="",S11=""),"M",1) -> M | BN11: =IF(AND(BI11="M",BJ11="M",BK11="M",BL11="M",BM11="M",D11=""),0,1) -> 1
A12: -87 | B12: =B13-1 -> 45838 | C12: =C13-1 -> 45838 | D12: A | T12: =IF(BN12=0,"M",IF(D12="p1",AL12,IF(D12="p2",AM12,IF(D12="A",0,((E12*F12)*G12/0.6)+((H12*I12)*J12/0.6)+((K12*L12)*M12/0.6)+((N12*O12)*P12/0.6)+((Q12*R12)*S12/0.6))))) -> 0 | U12: =IF(T12="M", "M", IF(T12>40, "YES", "NO")) -> NO | X12: =IF(T12="M",0,IF(T12=0,0,IF(T12>0,1,0))) -> 0 | AL12: =IF(AN12=1,AX12,IF(AN12=2,AR12,IF(AN12=3,AS12,IF(AN12=4,AT12,IF(AN12=5,AU12,IF(AN12=6,AV12,IF(AN12=7,AW12))))))) -> FALSE | AM12: =IF(AO12=1,BF12,IF(AO12=2,AZ12,IF(AO12=3,BA12,IF(AO12=4,BB12,IF(AO12=5,BC12,IF(AO12=6,BD12,IF(AO12=7,BE12))))))) -> FALSE | AN12: =IF(D12="p1",AQ12,"no") -> no | AO12: =IF(D12="p2",AQ12,"no") -> no | AQ12: =WEEKDAY(C12) -> 2 | AR12: =AR11 -> M | AS12: =AS11 -> M | AT12: =AT11 -> 0.70833333 | AU12: =AU11 -> M | AV12: =AV11 -> M | AW12: =AW11 -> 0.70833333 | AX12: =AX11 -> M | AZ12: =AZ11 -> 0 | BA12: =BA11 -> 0 | BB12: =BB11 -> 0 | BC12: =BC11 -> 0 | BD12: =BD11 -> 0 | BE12: =BE11 -> 0 | BF12: =BF11 -> 0 | BI12: =IF(OR(E12="",F12="",G12=""),"M",1) -> M | BJ12: =IF(OR(H12="",I12="",J12=""),"M",1) -> M | BK12: =IF(OR(K12="",L12="",M12=""),"M",1) -> M | BL12: =IF(OR(N12="",O12="",P12=""),"M",1) -> M | BM12: =IF(OR(Q12="",R12="",S12=""),"M",1) -> M | BN12: =IF(AND(BI12="M",BJ12="M",BK12="M",BL12="M",BM12="M",D12=""),0,1) -> 1
A13: -86 | B13: =B14-1 -> 45839 | C13: =C14-1 -> 45839 | D13: P1 | T13: =IF(BN13=0,"M",IF(D13="p1",AL13,IF(D13="p2",AM13,IF(D13="A",0,((E13*F13)*G13/0.6)+((H13*I13)*J13/0.6)+((K13*L13)*M13/0.6)+((N13*O13)*P13/0.6)+((Q13*R13)*S13/0.6))))) -> M | U13: =IF(T13="M", "M", IF(T13>40, "YES", "NO")) -> M | X13: =IF(T13="M",0,IF(T13=0,0,IF(T13>0,1,0))) -> 0 | AL13: =IF(AN13=1,AX13,IF(AN13=2,AR13,IF(AN13=3,AS13,IF(AN13=4,AT13,IF(AN13=5,AU13,IF(AN13=6,AV13,IF(AN13=7,AW13))))))) -> M | AM13: =IF(AO13=1,BF13,IF(AO13=2,AZ13,IF(AO13=3,BA13,IF(AO13=4,BB13,IF(AO13=5,BC13,IF(AO13=6,BD13,IF(AO13=7,BE13))))))) -> FALSE | AN13: =IF(D13="p1",AQ13,"no") -> 3 | AO13: =IF(D13="p2",AQ13,"no") -> no | AQ13: =WEEKDAY(C13) -> 3 | AR13: =AR12 -> M | AS13: =AS12 -> M | AT13: =AT12 -> 0.70833333 | AU13: =AU12 -> M | AV13: =AV12 -> M | AW13: =AW12 -> 0.70833333 | AX13: =AX12 -> M | AZ13: =AZ12 -> 0 | BA13: =BA12 -> 0 | BB13: =BB12 -> 0 | BC13: =BC12 -> 0 | BD13: =BD12 -> 0 | BE13: =BE12 -> 0 | BF13: =BF12 -> 0 | BI13: =IF(OR(E13="",F13="",G13=""),"M",1) -> M | BJ13: =IF(OR(H13="",I13="",J13=""),"M",1) -> M | BK13: =IF(OR(K13="",L13="",M13=""),"M",1) -> M | BL13: =IF(OR(N13="",O13="",P13=""),"M",1) -> M | BM13: =IF(OR(Q13="",R13="",S13=""),"M",1) -> M | BN13: =IF(AND(BI13="M",BJ13="M",BK13="M",BL13="M",BM13="M",D13=""),0,1) -> 1 | BQ13: =CONCATENATE("There ",BQ15," ",BQ16," ",BQ17," of missing drinking data in 90-day screening assessment period. ",BQ18) -> There are 84 days of missing drinking data in 90-day screening assessment period. Missing Baseline screening data must be collected prior to randomization.
A14: -85 | B14: =B15-1 -> 45840 | C14: =C15-1 -> 45840 | T14: =IF(BN14=0,"M",IF(D14="p1",AL14,IF(D14="p2",AM14,IF(D14="A",0,((E14*F14)*G14/0.6)+((H14*I14)*J14/0.6)+((K14*L14)*M14/0.6)+((N14*O14)*P14/0.6)+((Q14*R14)*S14/0.6))))) -> M | U14: =IF(T14="M", "M", IF(T14>40, "YES", "NO")) -> M | X14: =IF(T14="M",0,IF(T14=0,0,IF(T14>0,1,0))) -> 0 | AL14: =IF(AN14=1,AX14,IF(AN14=2,AR14,IF(AN14=3,AS14,IF(AN14=4,AT14,IF(AN14=5,AU14,IF(AN14=6,AV14,IF(AN14=7,AW14))))))) -> FALSE | AM14: =IF(AO14=1,BF14,IF(AO14=2,AZ14,IF(AO14=3,BA14,IF(AO14=4,BB14,IF(AO14=5,BC14,IF(AO14=6,BD14,IF(AO14=7,BE14))))))) -> FALSE | AN14: =IF(D14="p1",AQ14,"no") -> no | AO14: =IF(D14="p2",AQ14,"no") -> no | AQ14: =WEEKDAY(C14) -> 4 | AR14: =AR13 -> M | AS14: =AS13 -> M | AT14: =AT13 -> 0.70833333 | AU14: =AU13 -> M | AV14: =AV13 -> M | AW14: =AW13 -> 0.70833333 | AX14: =AX13 -> M | AZ14: =AZ13 -> 0 | BA14: =BA13 -> 0 | BB14: =BB13 -> 0 | BC14: =BC13 -> 0 | BD14: =BD13 -> 0 | BE14: =BE13 -> 0 | BF14: =BF13 -> 0 | BI14: =IF(OR(E14="",F14="",G14=""),"M",1) -> M | BJ14: =IF(OR(H14="",I14="",J14=""),"M",1) -> M | BK14: =IF(OR(K14="",L14="",M14=""),"M",1) -> M | BL14: =IF(OR(N14="",O14="",P14=""),"M",1) -> M | BM14: =IF(OR(Q14="",R14="",S14=""),"M",1) -> M | BN14: =IF(AND(BI14="M",BJ14="M",BK14="M",BL14="M",BM14="M",D14=""),0,1) -> 0
A15: -84 | B15: =B16-1 -> 45841 | C15: =C16-1 -> 45841 | T15: =IF(BN15=0,"M",IF(D15="p1",AL15,IF(D15="p2",AM15,IF(D15="A",0,((E15*F15)*G15/0.6)+((H15*I15)*J15/0.6)+((K15*L15)*M15/0.6)+((N15*O15)*P15/0.6)+((Q15*R15)*S15/0.6))))) -> M | U15: =IF(T15="M", "M", IF(T15>40, "YES", "NO")) -> M | X15: =IF(T15="M",0,IF(T15=0,0,IF(T15>0,1,0))) -> 0 | AL15: =IF(AN15=1,AX15,IF(AN15=2,AR15,IF(AN15=3,AS15,IF(AN15=4,AT15,IF(AN15=5,AU15,IF(AN15=6,AV15,IF(AN15=7,AW15))))))) -> FALSE | AM15: =IF(AO15=1,BF15,IF(AO15=2,AZ15,IF(AO15=3,BA15,IF(AO15=4,BB15,IF(AO15=5,BC15,IF(AO15=6,BD15,IF(AO15=7,BE15))))))) -> FALSE | AN15: =IF(D15="p1",AQ15,"no") -> no | AO15: =IF(D15="p2",AQ15,"no") -> no | AQ15: =WEEKDAY(C15) -> 5 | AR15: =AR14 -> M | AS15: =AS14 -> M | AT15: =AT14 -> 0.70833333 | AU15: =AU14 -> M | AV15: =AV14 -> M | AW15: =AW14 -> 0.70833333 | AX15: =AX14 -> M | AZ15: =AZ14 -> 0 | BA15: =BA14 -> 0 | BB15: =BB14 -> 0 | BC15: =BC14 -> 0 | BD15: =BD14 -> 0 | BE15: =BE14 -> 0 | BF15: =BF14 -> 0 | BI15: =IF(OR(E15="",F15="",G15=""),"M",1) -> M | BJ15: =IF(OR(H15="",I15="",J15=""),"M",1) -> M | BK15: =IF(OR(K15="",L15="",M15=""),"M",1) -> M | BL15: =IF(OR(N15="",O15="",P15=""),"M",1) -> M | BM15: =IF(OR(Q15="",R15="",S15=""),"M",1) -> M | BN15: =IF(AND(BI15="M",BJ15="M",BK15="M",BL15="M",BM15="M",D15=""),0,1) -> 0 | BQ15: =IF(BQ16=1,"is","are") -> are
A16: -83 | B16: =B17-1 -> 45842 | C16: =C17-1 -> 45842 | T16: =IF(BN16=0,"M",IF(D16="p1",AL16,IF(D16="p2",AM16,IF(D16="A",0,((E16*F16)*G16/0.6)+((H16*I16)*J16/0.6)+((K16*L16)*M16/0.6)+((N16*O16)*P16/0.6)+((Q16*R16)*S16/0.6))))) -> M | U16: =IF(T16="M", "M", IF(T16>40, "YES", "NO")) -> M | X16: =IF(T16="M",0,IF(T16=0,0,IF(T16>0,1,0))) -> 0 | AL16: =IF(AN16=1,AX16,IF(AN16=2,AR16,IF(AN16=3,AS16,IF(AN16=4,AT16,IF(AN16=5,AU16,IF(AN16=6,AV16,IF(AN16=7,AW16))))))) -> FALSE | AM16: =IF(AO16=1,BF16,IF(AO16=2,AZ16,IF(AO16=3,BA16,IF(AO16=4,BB16,IF(AO16=5,BC16,IF(AO16=6,BD16,IF(AO16=7,BE16))))))) -> FALSE | AN16: =IF(D16="p1",AQ16,"no") -> no | AO16: =IF(D16="p2",AQ16,"no") -> no | AQ16: =WEEKDAY(C16) -> 6 | AR16: =AR15 -> M | AS16: =AS15 -> M | AT16: =AT15 -> 0.70833333 | AU16: =AU15 -> M | AV16: =AV15 -> M | AW16: =AW15 -> 0.70833333 | AX16: =AX15 -> M | AZ16: =AZ15 -> 0 | BA16: =BA15 -> 0 | BB16: =BB15 -> 0 | BC16: =BC15 -> 0 | BD16: =BD15 -> 0 | BE16: =BE15 -> 0 | BF16: =BF15 -> 0 | BI16: =IF(OR(E16="",F16="",G16=""),"M",1) -> M | BJ16: =IF(OR(H16="",I16="",J16=""),"M",1) -> M | BK16: =IF(OR(K16="",L16="",M16=""),"M",1) -> M | BL16: =IF(OR(N16="",O16="",P16=""),"M",1) -> M | BM16: =IF(OR(Q16="",R16="",S16=""),"M",1) -> M | BN16: =IF(AND(BI16="M",BJ16="M",BK16="M",BL16="M",BM16="M",D16=""),0,1) -> 0 | BQ16: =BO10-BO9 -> 84
A17: -82 | B17: =B18-1 -> 45843 | C17: =C18-1 -> 45843 | T17: =IF(BN17=0,"M",IF(D17="p1",AL17,IF(D17="p2",AM17,IF(D17="A",0,((E17*F17)*G17/0.6)+((H17*I17)*J17/0.6)+((K17*L17)*M17/0.6)+((N17*O17)*P17/0.6)+((Q17*R17)*S17/0.6))))) -> M | U17: =IF(T17="M", "M", IF(T17>40, "YES", "NO")) -> M | X17: =IF(T17="M",0,IF(T17=0,0,IF(T17>0,1,0))) -> 0 | AL17: =IF(AN17=1,AX17,IF(AN17=2,AR17,IF(AN17=3,AS17,IF(AN17=4,AT17,IF(AN17=5,AU17,IF(AN17=6,AV17,IF(AN17=7,AW17))))))) -> FALSE | AM17: =IF(AO17=1,BF17,IF(AO17=2,AZ17,IF(AO17=3,BA17,IF(AO17=4,BB17,IF(AO17=5,BC17,IF(AO17=6,BD17,IF(AO17=7,BE17))))))) -> FALSE | AN17: =IF(D17="p1",AQ17,"no") -> no | AO17: =IF(D17="p2",AQ17,"no") -> no | AQ17: =WEEKDAY(C17) -> 7 | AR17: =AR16 -> M | AS17: =AS16 -> M | AT17: =AT16 -> 0.70833333 | AU17: =AU16 -> M | AV17: =AV16 -> M | AW17: =AW16 -> 0.70833333 | AX17: =AX16 -> M | AZ17: =AZ16 -> 0 | BA17: =BA16 -> 0 | BB17: =BB16 -> 0 | BC17: =BC16 -> 0 | BD17: =BD16 -> 0 | BE17: =BE16 -> 0 | BF17: =BF16 -> 0 | BI17: =IF(OR(E17="",F17="",G17=""),"M",1) -> M | BJ17: =IF(OR(H17="",I17="",J17=""),"M",1) -> M | BK17: =IF(OR(K17="",L17="",M17=""),"M",1) -> M | BL17: =IF(OR(N17="",O17="",P17=""),"M",1) -> M | BM17: =IF(OR(Q17="",R17="",S17=""),"M",1) -> M | BN17: =IF(AND(BI17="M",BJ17="M",BK17="M",BL17="M",BM17="M",D17=""),0,1) -> 0 | BQ17: =IF(BQ16=1,"day","days") -> days
A18: -81 | B18: =B19-1 -> 45844 | C18: =C19-1 -> 45844 | T18: =IF(BN18=0,"M",IF(D18="p1",AL18,IF(D18="p2",AM18,IF(D18="A",0,((E18*F18)*G18/0.6)+((H18*I18)*J18/0.6)+((K18*L18)*M18/0.6)+((N18*O18)*P18/0.6)+((Q18*R18)*S18/0.6))))) -> M | U18: =IF(T18="M", "M", IF(T18>40, "YES", "NO")) -> M | X18: =IF(T18="M",0,IF(T18=0,0,IF(T18>0,1,0))) -> 0 | AL18: =IF(AN18=1,AX18,IF(AN18=2,AR18,IF(AN18=3,AS18,IF(AN18=4,AT18,IF(AN18=5,AU18,IF(AN18=6,AV18,IF(AN18=7,AW18))))))) -> FALSE | AM18: =IF(AO18=1,BF18,IF(AO18=2,AZ18,IF(AO18=3,BA18,IF(AO18=4,BB18,IF(AO18=5,BC18,IF(AO18=6,BD18,IF(AO18=7,BE18))))))) -> FALSE | AN18: =IF(D18="p1",AQ18,"no") -> no | AO18: =IF(D18="p2",AQ18,"no") -> no | AQ18: =WEEKDAY(C18) -> 1 | AR18: =AR17 -> M | AS18: =AS17 -> M | AT18: =AT17 -> 0.70833333 | AU18: =AU17 -> M | AV18: =AV17 -> M | AW18: =AW17 -> 0.70833333 | AX18: =AX17 -> M | AZ18: =AZ17 -> 0 | BA18: =BA17 -> 0 | BB18: =BB17 -> 0 | BC18: =BC17 -> 0 | BD18: =BD17 -> 0 | BE18: =BE17 -> 0 | BF18: =BF17 -> 0 | BI18: =IF(OR(E18="",F18="",G18=""),"M",1) -> M | BJ18: =IF(OR(H18="",I18="",J18=""),"M",1) -> M | BK18: =IF(OR(K18="",L18="",M18=""),"M",1) -> M | BL18: =IF(OR(N18="",O18="",P18=""),"M",1) -> M | BM18: =IF(OR(Q18="",R18="",S18=""),"M",1) -> M | BN18: =IF(AND(BI18="M",BJ18="M",BK18="M",BL18="M",BM18="M",D18=""),0,1) -> 0 | BQ18: Missing Baseline screening data must be collected prior to randomization.
A19: -80 | B19: =B20-1 -> 45845 | C19: =C20-1 -> 45845 | T19: =IF(BN19=0,"M",IF(D19="p1",AL19,IF(D19="p2",AM19,IF(D19="A",0,((E19*F19)*G19/0.6)+((H19*I19)*J19/0.6)+((K19*L19)*M19/0.6)+((N19*O19)*P19/0.6)+((Q19*R19)*S19/0.6))))) -> M | U19: =IF(T19="M", "M", IF(T19>40, "YES", "NO")) -> M | X19: =IF(T19="M",0,IF(T19=0,0,IF(T19>0,1,0))) -> 0 | AL19: =IF(AN19=1,AX19,IF(AN19=2,AR19,IF(AN19=3,AS19,IF(AN19=4,AT19,IF(AN19=5,AU19,IF(AN19=6,AV19,IF(AN19=7,AW19))))))) -> FALSE | AM19: =IF(AO19=1,BF19,IF(AO19=2,AZ19,IF(AO19=3,BA19,IF(AO19=4,BB19,IF(AO19=5,BC19,IF(AO19=6,BD19,IF(AO19=7,BE19))))))) -> FALSE | AN19: =IF(D19="p1",AQ19,"no") -> no | AO19: =IF(D19="p2",AQ19,"no") -> no | AQ19: =WEEKDAY(C19) -> 2 | AR19: =AR18 -> M | AS19: =AS18 -> M | AT19: =AT18 -> 0.70833333 | AU19: =AU18 -> M | AV19: =AV18 -> M | AW19: =AW18 -> 0.70833333 | AX19: =AX18 -> M | AZ19: =AZ18 -> 0 | BA19: =BA18 -> 0 | BB19: =BB18 -> 0 | BC19: =BC18 -> 0 | BD19: =BD18 -> 0 | BE19: =BE18 -> 0 | BF19: =BF18 -> 0 | BI19: =IF(OR(E19="",F19="",G19=""),"M",1) -> M | BJ19: =IF(OR(H19="",I19="",J19=""),"M",1) -> M | BK19: =IF(OR(K19="",L19="",M19=""),"M",1) -> M | BL19: =IF(OR(N19="",O19="",P19=""),"M",1) -> M | BM19: =IF(OR(Q19="",R19="",S19=""),"M",1) -> M | BN19: =IF(AND(BI19="M",BJ19="M",BK19="M",BL19="M",BM19="M",D19=""),0,1) -> 0 | BQ19: Screening Drinking Data Complete
A20: -79 | B20: =B21-1 -> 45846 | C20: =C21-1 -> 45846 | D20: P1 | T20: =IF(BN20=0,"M",IF(D20="p1",AL20,IF(D20="p2",AM20,IF(D20="A",0,((E20*F20)*G20/0.6)+((H20*I20)*J20/0.6)+((K20*L20)*M20/0.6)+((N20*O20)*P20/0.6)+((Q20*R20)*S20/0.6))))) -> M | U20: =IF(T20="M", "M", IF(T20>40, "YES", "NO")) -> M | X20: =IF(T20="M",0,IF(T20=0,0,IF(T20>0,1,0))) -> 0 | AL20: =IF(AN20=1,AX20,IF(AN20=2,AR20,IF(AN20=3,AS20,IF(AN20=4,AT20,IF(AN20=5,AU20,IF(AN20=6,AV20,IF(AN20=7,AW20))))))) -> M | AM20: =IF(AO20=1,BF20,IF(AO20=2,AZ20,IF(AO20=3,BA20,IF(AO20=4,BB20,IF(AO20=5,BC20,IF(AO20=6,BD20,IF(AO20=7,BE20))))))) -> FALSE | AN20: =IF(D20="p1",AQ20,"no") -> 3 | AO20: =IF(D20="p2",AQ20,"no") -> no | AQ20: =WEEKDAY(C20) -> 3 | AR20: =AR19 -> M | AS20: =AS19 -> M | AT20: =AT19 -> 0.70833333 | AU20: =AU19 -> M | AV20: =AV19 -> M | AW20: =AW19 -> 0.70833333 | AX20: =AX19 -> M | AZ20: =AZ19 -> 0 | BA20: =BA19 -> 0 | BB20: =BB19 -> 0 | BC20: =BC19 -> 0 | BD20: =BD19 -> 0 | BE20: =BE19 -> 0 | BF20: =BF19 -> 0 | BI20: =IF(OR(E20="",F20="",G20=""),"M",1) -> M | BJ20: =IF(OR(H20="",I20="",J20=""),"M",1) -> M | BK20: =IF(OR(K20="",L20="",M20=""),"M",1) -> M | BL20: =IF(OR(N20="",O20="",P20=""),"M",1) -> M | BM20: =IF(OR(Q20="",R20="",S20=""),"M",1) -> M | BN20: =IF(AND(BI20="M",BJ20="M",BK20="M",BL20="M",BM20="M",D20=""),0,1) -> 1
A21: -78 | B21: =B22-1 -> 45847 | C21: =C22-1 -> 45847 | T21: =IF(BN21=0,"M",IF(D21="p1",AL21,IF(D21="p2",AM21,IF(D21="A",0,((E21*F21)*G21/0.6)+((H21*I21)*J21/0.6)+((K21*L21)*M21/0.6)+((N21*O21)*P21/0.6)+((Q21*R21)*S21/0.6))))) -> M | U21: =IF(T21="M", "M", IF(T21>40, "YES", "NO")) -> M | X21: =IF(T21="M",0,IF(T21=0,0,IF(T21>0,1,0))) -> 0 | AL21: =IF(AN21=1,AX21,IF(AN21=2,AR21,IF(AN21=3,AS21,IF(AN21=4,AT21,IF(AN21=5,AU21,IF(AN21=6,AV21,IF(AN21=7,AW21))))))) -> FALSE | AM21: =IF(AO21=1,BF21,IF(AO21=2,AZ21,IF(AO21=3,BA21,IF(AO21=4,BB21,IF(AO21=5,BC21,IF(AO21=6,BD21,IF(AO21=7,BE21))))))) -> FALSE | AN21: =IF(D21="p1",AQ21,"no") -> no | AO21: =IF(D21="p2",AQ21,"no") -> no | AQ21: =WEEKDAY(C21) -> 4 | AR21: =AR20 -> M | AS21: =AS20 -> M | AT21: =AT20 -> 0.70833333 | AU21: =AU20 -> M | AV21: =AV20 -> M | AW21: =AW20 -> 0.70833333 | AX21: =AX20 -> M | AZ21: =AZ20 -> 0 | BA21: =BA20 -> 0 | BB21: =BB20 -> 0 | BC21: =BC20 -> 0 | BD21: =BD20 -> 0 | BE21: =BE20 -> 0 | BF21: =BF20 -> 0 | BI21: =IF(OR(E21="",F21="",G21=""),"M",1) -> M | BJ21: =IF(OR(H21="",I21="",J21=""),"M",1) -> M | BK21: =IF(OR(K21="",L21="",M21=""),"M",1) -> M | BL21: =IF(OR(N21="",O21="",P21=""),"M",1) -> M | BM21: =IF(OR(Q21="",R21="",S21=""),"M",1) -> M | BN21: =IF(AND(BI21="M",BJ21="M",BK21="M",BL21="M",BM21="M",D21=""),0,1) -> 0
A22: -77 | B22: =B23-1 -> 45848 | C22: =C23-1 -> 45848 | T22: =IF(BN22=0,"M",IF(D22="p1",AL22,IF(D22="p2",AM22,IF(D22="A",0,((E22*F22)*G22/0.6)+((H22*I22)*J22/0.6)+((K22*L22)*M22/0.6)+((N22*O22)*P22/0.6)+((Q22*R22)*S22/0.6))))) -> M | U22: =IF(T22="M", "M", IF(T22>40, "YES", "NO")) -> M | X22: =IF(T22="M",0,IF(T22=0,0,IF(T22>0,1,0))) -> 0 | AL22: =IF(AN22=1,AX22,IF(AN22=2,AR22,IF(AN22=3,AS22,IF(AN22=4,AT22,IF(AN22=5,AU22,IF(AN22=6,AV22,IF(AN22=7,AW22))))))) -> FALSE | AM22: =IF(AO22=1,BF22,IF(AO22=2,AZ22,IF(AO22=3,BA22,IF(AO22=4,BB22,IF(AO22=5,BC22,IF(AO22=6,BD22,IF(AO22=7,BE22))))))) -> FALSE | AN22: =IF(D22="p1",AQ22,"no") -> no | AO22: =IF(D22="p2",AQ22,"no") -> no | AQ22: =WEEKDAY(C22) -> 5 | AR22: =AR21 -> M | AS22: =AS21 -> M | AT22: =AT21 -> 0.70833333 | AU22: =AU21 -> M | AV22: =AV21 -> M | AW22: =AW21 -> 0.70833333 | AX22: =AX21 -> M | AZ22: =AZ21 -> 0 | BA22: =BA21 -> 0 | BB22: =BB21 -> 0 | BC22: =BC21 -> 0 | BD22: =BD21 -> 0 | BE22: =BE21 -> 0 | BF22: =BF21 -> 0 | BI22: =IF(OR(E22="",F22="",G22=""),"M",1) -> M | BJ22: =IF(OR(H22="",I22="",J22=""),"M",1) -> M | BK22: =IF(OR(K22="",L22="",M22=""),"M",1) -> M | BL22: =IF(OR(N22="",O22="",P22=""),"M",1) -> M | BM22: =IF(OR(Q22="",R22="",S22=""),"M",1) -> M | BN22: =IF(AND(BI22="M",BJ22="M",BK22="M",BL22="M",BM22="M",D22=""),0,1) -> 0
A23: -76 | B23: =B24-1 -> 45849 | C23: =C24-1 -> 45849 | T23: =IF(BN23=0,"M",IF(D23="p1",AL23,IF(D23="p2",AM23,IF(D23="A",0,((E23*F23)*G23/0.6)+((H23*I23)*J23/0.6)+((K23*L23)*M23/0.6)+((N23*O23)*P23/0.6)+((Q23*R23)*S23/0.6))))) -> M | U23: =IF(T23="M", "M", IF(T23>40, "YES", "NO")) -> M | X23: =IF(T23="M",0,IF(T23=0,0,IF(T23>0,1,0))) -> 0 | AL23: =IF(AN23=1,AX23,IF(AN23=2,AR23,IF(AN23=3,AS23,IF(AN23=4,AT23,IF(AN23=5,AU23,IF(AN23=6,AV23,IF(AN23=7,AW23))))))) -> FALSE | AM23: =IF(AO23=1,BF23,IF(AO23=2,AZ23,IF(AO23=3,BA23,IF(AO23=4,BB23,IF(AO23=5,BC23,IF(AO23=6,BD23,IF(AO23=7,BE23))))))) -> FALSE | AN23: =IF(D23="p1",AQ23,"no") -> no | AO23: =IF(D23="p2",AQ23,"no") -> no | AQ23: =WEEKDAY(C23) -> 6 | AR23: =AR22 -> M | AS23: =AS22 -> M | AT23: =AT22 -> 0.70833333 | AU23: =AU22 -> M | AV23: =AV22 -> M | AW23: =AW22 -> 0.70833333 | AX23: =AX22 -> M | AZ23: =AZ22 -> 0 | BA23: =BA22 -> 0 | BB23: =BB22 -> 0 | BC23: =BC22 -> 0 | BD23: =BD22 -> 0 | BE23: =BE22 -> 0 | BF23: =BF22 -> 0 | BI23: =IF(OR(E23="",F23="",G23=""),"M",1) -> M | BJ23: =IF(OR(H23="",I23="",J23=""),"M",1) -> M | BK23: =IF(OR(K23="",L23="",M23=""),"M",1) -> M | BL23: =IF(OR(N23="",O23="",P23=""),"M",1) -> M | BM23: =IF(OR(Q23="",R23="",S23=""),"M",1) -> M | BN23: =IF(AND(BI23="M",BJ23="M",BK23="M",BL23="M",BM23="M",D23=""),0,1) -> 0
A24: -75 | B24: =B25-1 -> 45850 | C24: =C25-1 -> 45850 | T24: =IF(BN24=0,"M",IF(D24="p1",AL24,IF(D24="p2",AM24,IF(D24="A",0,((E24*F24)*G24/0.6)+((H24*I24)*J24/0.6)+((K24*L24)*M24/0.6)+((N24*O24)*P24/0.6)+((Q24*R24)*S24/0.6))))) -> M | U24: =IF(T24="M", "M", IF(T24>40, "YES", "NO")) -> M | X24: =IF(T24="M",0,IF(T24=0,0,IF(T24>0,1,0))) -> 0 | AL24: =IF(AN24=1,AX24,IF(AN24=2,AR24,IF(AN24=3,AS24,IF(AN24=4,AT24,IF(AN24=5,AU24,IF(AN24=6,AV24,IF(AN24=7,AW24))))))) -> FALSE | AM24: =IF(AO24=1,BF24,IF(AO24=2,AZ24,IF(AO24=3,BA24,IF(AO24=4,BB24,IF(AO24=5,BC24,IF(AO24=6,BD24,IF(AO24=7,BE24))))))) -> FALSE | AN24: =IF(D24="p1",AQ24,"no") -> no | AO24: =IF(D24="p2",AQ24,"no") -> no | AQ24: =WEEKDAY(C24) -> 7 | AR24: =AR23 -> M | AS24: =AS23 -> M | AT24: =AT23 -> 0.70833333 | AU24: =AU23 -> M | AV24: =AV23 -> M | AW24: =AW23 -> 0.70833333 | AX24: =AX23 -> M | AZ24: =AZ23 -> 0 | BA24: =BA23 -> 0 | BB24: =BB23 -> 0 | BC24: =BC23 -> 0 | BD24: =BD23 -> 0 | BE24: =BE23 -> 0 | BF24: =BF23 -> 0 | BI24: =IF(OR(E24="",F24="",G24=""),"M",1) -> M | BJ24: =IF(OR(H24="",I24="",J24=""),"M",1) -> M | BK24: =IF(OR(K24="",L24="",M24=""),"M",1) -> M | BL24: =IF(OR(N24="",O24="",P24=""),"M",1) -> M | BM24: =IF(OR(Q24="",R24="",S24=""),"M",1) -> M | BN24: =IF(AND(BI24="M",BJ24="M",BK24="M",BL24="M",BM24="M",D24=""),0,1) -> 0
A25: -74 | B25: =B26-1 -> 45851 | C25: =C26-1 -> 45851 | T25: =IF(BN25=0,"M",IF(D25="p1",AL25,IF(D25="p2",AM25,IF(D25="A",0,((E25*F25)*G25/0.6)+((H25*I25)*J25/0.6)+((K25*L25)*M25/0.6)+((N25*O25)*P25/0.6)+((Q25*R25)*S25/0.6))))) -> M | U25: =IF(T25="M", "M", IF(T25>40, "YES", "NO")) -> M | X25: =IF(T25="M",0,IF(T25=0,0,IF(T25>0,1,0))) -> 0 | AL25: =IF(AN25=1,AX25,IF(AN25=2,AR25,IF(AN25=3,AS25,IF(AN25=4,AT25,IF(AN25=5,AU25,IF(AN25=6,AV25,IF(AN25=7,AW25))))))) -> FALSE | AM25: =IF(AO25=1,BF25,IF(AO25=2,AZ25,IF(AO25=3,BA25,IF(AO25=4,BB25,IF(AO25=5,BC25,IF(AO25=6,BD25,IF(AO25=7,BE25))))))) -> FALSE | AN25: =IF(D25="p1",AQ25,"no") -> no | AO25: =IF(D25="p2",AQ25,"no") -> no | AQ25: =WEEKDAY(C25) -> 1 | AR25: =AR24 -> M | AS25: =AS24 -> M | AT25: =AT24 -> 0.70833333 | AU25: =AU24 -> M | AV25: =AV24 -> M | AW25: =AW24 -> 0.70833333 | AX25: =AX24 -> M | AZ25: =AZ24 -> 0 | BA25: =BA24 -> 0 | BB25: =BB24 -> 0 | BC25: =BC24 -> 0 | BD25: =BD24 -> 0 | BE25: =BE24 -> 0 | BF25: =BF24 -> 0 | BI25: =IF(OR(E25="",F25="",G25=""),"M",1) -> M | BJ25: =IF(OR(H25="",I25="",J25=""),"M",1) -> M | BK25: =IF(OR(K25="",L25="",M25=""),"M",1) -> M | BL25: =IF(OR(N25="",O25="",P25=""),"M",1) -> M | BM25: =IF(OR(Q25="",R25="",S25=""),"M",1) -> M | BN25: =IF(AND(BI25="M",BJ25="M",BK25="M",BL25="M",BM25="M",D25=""),0,1) -> 0
A26: -73 | B26: =B27-1 -> 45852 | C26: =C27-1 -> 45852 | T26: =IF(BN26=0,"M",IF(D26="p1",AL26,IF(D26="p2",AM26,IF(D26="A",0,((E26*F26)*G26/0.6)+((H26*I26)*J26/0.6)+((K26*L26)*M26/0.6)+((N26*O26)*P26/0.6)+((Q26*R26)*S26/0.6))))) -> M | U26: =IF(T26="M", "M", IF(T26>40, "YES", "NO")) -> M | X26: =IF(T26="M",0,IF(T26=0,0,IF(T26>0,1,0))) -> 0 | AL26: =IF(AN26=1,AX26,IF(AN26=2,AR26,IF(AN26=3,AS26,IF(AN26=4,AT26,IF(AN26=5,AU26,IF(AN26=6,AV26,IF(AN26=7,AW26))))))) -> FALSE | AM26: =IF(AO26=1,BF26,IF(AO26=2,AZ26,IF(AO26=3,BA26,IF(AO26=4,BB26,IF(AO26=5,BC26,IF(AO26=6,BD26,IF(AO26=7,BE26))))))) -> FALSE | AN26: =IF(D26="p1",AQ26,"no") -> no | AO26: =IF(D26="p2",AQ26,"no") -> no | AQ26: =WEEKDAY(C26) -> 2 | AR26: =AR25 -> M | AS26: =AS25 -> M | AT26: =AT25 -> 0.70833333 | AU26: =AU25 -> M | AV26: =AV25 -> M | AW26: =AW25 -> 0.70833333 | AX26: =AX25 -> M | AZ26: =AZ25 -> 0 | BA26: =BA25 -> 0 | BB26: =BB25 -> 0 | BC26: =BC25 -> 0 | BD26: =BD25 -> 0 | BE26: =BE25 -> 0 | BF26: =BF25 -> 0 | BI26: =IF(OR(E26="",F26="",G26=""),"M",1) -> M | BJ26: =IF(OR(H26="",I26="",J26=""),"M",1) -> M | BK26: =IF(OR(K26="",L26="",M26=""),"M",1) -> M | BL26: =IF(OR(N26="",O26="",P26=""),"M",1) -> M | BM26: =IF(OR(Q26="",R26="",S26=""),"M",1) -> M | BN26: =IF(AND(BI26="M",BJ26="M",BK26="M",BL26="M",BM26="M",D26=""),0,1) -> 0
A27: -72 | B27: =B28-1 -> 45853 | C27: =C28-1 -> 45853 | T27: =IF(BN27=0,"M",IF(D27="p1",AL27,IF(D27="p2",AM27,IF(D27="A",0,((E27*F27)*G27/0.6)+((H27*I27)*J27/0.6)+((K27*L27)*M27/0.6)+((N27*O27)*P27/0.6)+((Q27*R27)*S27/0.6))))) -> M | U27: =IF(T27="M", "M", IF(T27>40, "YES", "NO")) -> M | X27: =IF(T27="M",0,IF(T27=0,0,IF(T27>0,1,0))) -> 0 | AL27: =IF(AN27=1,AX27,IF(AN27=2,AR27,IF(AN27=3,AS27,IF(AN27=4,AT27,IF(AN27=5,AU27,IF(AN27=6,AV27,IF(AN27=7,AW27))))))) -> FALSE | AM27: =IF(AO27=1,BF27,IF(AO27=2,AZ27,IF(AO27=3,BA27,IF(AO27=4,BB27,IF(AO27=5,BC27,IF(AO27=6,BD27,IF(AO27=7,BE27))))))) -> FALSE | AN27: =IF(D27="p1",AQ27,"no") -> no | AO27: =IF(D27="p2",AQ27,"no") -> no | AQ27: =WEEKDAY(C27) -> 3 | AR27: =AR26 -> M | AS27: =AS26 -> M | AT27: =AT26 -> 0.70833333 | AU27: =AU26 -> M | AV27: =AV26 -> M | AW27: =AW26 -> 0.70833333 | AX27: =AX26 -> M | AZ27: =AZ26 -> 0 | BA27: =BA26 -> 0 | BB27: =BB26 -> 0 | BC27: =BC26 -> 0 | BD27: =BD26 -> 0 | BE27: =BE26 -> 0 | BF27: =BF26 -> 0 | BI27: =IF(OR(E27="",F27="",G27=""),"M",1) -> M | BJ27: =IF(OR(H27="",I27="",J27=""),"M",1) -> M | BK27: =IF(OR(K27="",L27="",M27=""),"M",1) -> M | BL27: =IF(OR(N27="",O27="",P27=""),"M",1) -> M | BM27: =IF(OR(Q27="",R27="",S27=""),"M",1) -> M | BN27: =IF(AND(BI27="M",BJ27="M",BK27="M",BL27="M",BM27="M",D27=""),0,1) -> 0
A28: -71 | B28: =B29-1 -> 45854 | C28: =C29-1 -> 45854 | T28: =IF(BN28=0,"M",IF(D28="p1",AL28,IF(D28="p2",AM28,IF(D28="A",0,((E28*F28)*G28/0.6)+((H28*I28)*J28/0.6)+((K28*L28)*M28/0.6)+((N28*O28)*P28/0.6)+((Q28*R28)*S28/0.6))))) -> M | U28: =IF(T28="M", "M", IF(T28>40, "YES", "NO")) -> M | X28: =IF(T28="M",0,IF(T28=0,0,IF(T28>0,1,0))) -> 0 | AL28: =IF(AN28=1,AX28,IF(AN28=2,AR28,IF(AN28=3,AS28,IF(AN28=4,AT28,IF(AN28=5,AU28,IF(AN28=6,AV28,IF(AN28=7,AW28))))))) -> FALSE | AM28: =IF(AO28=1,BF28,IF(AO28=2,AZ28,IF(AO28=3,BA28,IF(AO28=4,BB28,IF(AO28=5,BC28,IF(AO28=6,BD28,IF(AO28=7,BE28))))))) -> FALSE | AN28: =IF(D28="p1",AQ28,"no") -> no | AO28: =IF(D28="p2",AQ28,"no") -> no | AQ28: =WEEKDAY(C28) -> 4 | AR28: =AR27 -> M | AS28: =AS27 -> M | AT28: =AT27 -> 0.70833333 | AU28: =AU27 -> M | AV28: =AV27 -> M | AW28: =AW27 -> 0.70833333 | AX28: =AX27 -> M | AZ28: =AZ27 -> 0 | BA28: =BA27 -> 0 | BB28: =BB27 -> 0 | BC28: =BC27 -> 0 | BD28: =BD27 -> 0 | BE28: =BE27 -> 0 | BF28: =BF27 -> 0 | BI28: =IF(OR(E28="",F28="",G28=""),"M",1) -> M | BJ28: =IF(OR(H28="",I28="",J28=""),"M",1) -> M | BK28: =IF(OR(K28="",L28="",M28=""),"M",1) -> M | BL28: =IF(OR(N28="",O28="",P28=""),"M",1) -> M | BM28: =IF(OR(Q28="",R28="",S28=""),"M",1) -> M | BN28: =IF(AND(BI28="M",BJ28="M",BK28="M",BL28="M",BM28="M",D28=""),0,1) -> 0
A29: -70 | B29: =B30-1 -> 45855 | C29: =C30-1 -> 45855 | T29: =IF(BN29=0,"M",IF(D29="p1",AL29,IF(D29="p2",AM29,IF(D29="A",0,((E29*F29)*G29/0.6)+((H29*I29)*J29/0.6)+((K29*L29)*M29/0.6)+((N29*O29)*P29/0.6)+((Q29*R29)*S29/0.6))))) -> M | U29: =IF(T29="M", "M", IF(T29>40, "YES", "NO")) -> M | X29: =IF(T29="M",0,IF(T29=0,0,IF(T29>0,1,0))) -> 0 | AL29: =IF(AN29=1,AX29,IF(AN29=2,AR29,IF(AN29=3,AS29,IF(AN29=4,AT29,IF(AN29=5,AU29,IF(AN29=6,AV29,IF(AN29=7,AW29))))))) -> FALSE | AM29: =IF(AO29=1,BF29,IF(AO29=2,AZ29,IF(AO29=3,BA29,IF(AO29=4,BB29,IF(AO29=5,BC29,IF(AO29=6,BD29,IF(AO29=7,BE29))))))) -> FALSE | AN29: =IF(D29="p1",AQ29,"no") -> no | AO29: =IF(D29="p2",AQ29,"no") -> no | AQ29: =WEEKDAY(C29) -> 5 | AR29: =AR28 -> M | AS29: =AS28 -> M | AT29: =AT28 -> 0.70833333 | AU29: =AU28 -> M | AV29: =AV28 -> M | AW29: =AW28 -> 0.70833333 | AX29: =AX28 -> M | AZ29: =AZ28 -> 0 | BA29: =BA28 -> 0 | BB29: =BB28 -> 0 | BC29: =BC28 -> 0 | BD29: =BD28 -> 0 | BE29: =BE28 -> 0 | BF29: =BF28 -> 0 | BI29: =IF(OR(E29="",F29="",G29=""),"M",1) -> M | BJ29: =IF(OR(H29="",I29="",J29=""),"M",1) -> M | BK29: =IF(OR(K29="",L29="",M29=""),"M",1) -> M | BL29: =IF(OR(N29="",O29="",P29=""),"M",1) -> M | BM29: =IF(OR(Q29="",R29="",S29=""),"M",1) -> M | BN29: =IF(AND(BI29="M",BJ29="M",BK29="M",BL29="M",BM29="M",D29=""),0,1) -> 0
A30: -69 | B30: =B31-1 -> 45856 | C30: =C31-1 -> 45856 | T30: =IF(BN30=0,"M",IF(D30="p1",AL30,IF(D30="p2",AM30,IF(D30="A",0,((E30*F30)*G30/0.6)+((H30*I30)*J30/0.6)+((K30*L30)*M30/0.6)+((N30*O30)*P30/0.6)+((Q30*R30)*S30/0.6))))) -> M | U30: =IF(T30="M", "M", IF(T30>40, "YES", "NO")) -> M | X30: =IF(T30="M",0,IF(T30=0,0,IF(T30>0,1,0))) -> 0 | AL30: =IF(AN30=1,AX30,IF(AN30=2,AR30,IF(AN30=3,AS30,IF(AN30=4,AT30,IF(AN30=5,AU30,IF(AN30=6,AV30,IF(AN30=7,AW30))))))) -> FALSE | AM30: =IF(AO30=1,BF30,IF(AO30=2,AZ30,IF(AO30=3,BA30,IF(AO30=4,BB30,IF(AO30=5,BC30,IF(AO30=6,BD30,IF(AO30=7,BE30))))))) -> FALSE | AN30: =IF(D30="p1",AQ30,"no") -> no | AO30: =IF(D30="p2",AQ30,"no") -> no | AQ30: =WEEKDAY(C30) -> 6 | AR30: =AR29 -> M | AS30: =AS29 -> M | AT30: =AT29 -> 0.70833333 | AU30: =AU29 -> M | AV30: =AV29 -> M | AW30: =AW29 -> 0.70833333 | AX30: =AX29 -> M | AZ30: =AZ29 -> 0 | BA30: =BA29 -> 0 | BB30: =BB29 -> 0 | BC30: =BC29 -> 0 | BD30: =BD29 -> 0 | BE30: =BE29 -> 0 | BF30: =BF29 -> 0 | BI30: =IF(OR(E30="",F30="",G30=""),"M",1) -> M | BJ30: =IF(OR(H30="",I30="",J30=""),"M",1) -> M | BK30: =IF(OR(K30="",L30="",M30=""),"M",1) -> M | BL30: =IF(OR(N30="",O30="",P30=""),"M",1) -> M | BM30: =IF(OR(Q30="",R30="",S30=""),"M",1) -> M | BN30: =IF(AND(BI30="M",BJ30="M",BK30="M",BL30="M",BM30="M",D30=""),0,1) -> 0
A31: -68 | B31: =B32-1 -> 45857 | C31: =C32-1 -> 45857 | T31: =IF(BN31=0,"M",IF(D31="p1",AL31,IF(D31="p2",AM31,IF(D31="A",0,((E31*F31)*G31/0.6)+((H31*I31)*J31/0.6)+((K31*L31)*M31/0.6)+((N31*O31)*P31/0.6)+((Q31*R31)*S31/0.6))))) -> M | U31: =IF(T31="M", "M", IF(T31>40, "YES", "NO")) -> M | X31: =IF(T31="M",0,IF(T31=0,0,IF(T31>0,1,0))) -> 0 | AL31: =IF(AN31=1,AX31,IF(AN31=2,AR31,IF(AN31=3,AS31,IF(AN31=4,AT31,IF(AN31=5,AU31,IF(AN31=6,AV31,IF(AN31=7,AW31))))))) -> FALSE | AM31: =IF(AO31=1,BF31,IF(AO31=2,AZ31,IF(AO31=3,BA31,IF(AO31=4,BB31,IF(AO31=5,BC31,IF(AO31=6,BD31,IF(AO31=7,BE31))))))) -> FALSE | AN31: =IF(D31="p1",AQ31,"no") -> no | AO31: =IF(D31="p2",AQ31,"no") -> no | AQ31: =WEEKDAY(C31) -> 7 | AR31: =AR30 -> M | AS31: =AS30 -> M | AT31: =AT30 -> 0.70833333 | AU31: =AU30 -> M | AV31: =AV30 -> M | AW31: =AW30 -> 0.70833333 | AX31: =AX30 -> M | AZ31: =AZ30 -> 0 | BA31: =BA30 -> 0 | BB31: =BB30 -> 0 | BC31: =BC30 -> 0 | BD31: =BD30 -> 0 | BE31: =BE30 -> 0 | BF31: =BF30 -> 0 | BI31: =IF(OR(E31="",F31="",G31=""),"M",1) -> M | BJ31: =IF(OR(H31="",I31="",J31=""),"M",1) -> M | BK31: =IF(OR(K31="",L31="",M31=""),"M",1) -> M | BL31: =IF(OR(N31="",O31="",P31=""),"M",1) -> M | BM31: =IF(OR(Q31="",R31="",S31=""),"M",1) -> M | BN31: =IF(AND(BI31="M",BJ31="M",BK31="M",BL31="M",BM31="M",D31=""),0,1) -> 0
A32: -67 | B32: =B33-1 -> 45858 | C32: =C33-1 -> 45858 | T32: =IF(BN32=0,"M",IF(D32="p1",AL32,IF(D32="p2",AM32,IF(D32="A",0,((E32*F32)*G32/0.6)+((H32*I32)*J32/0.6)+((K32*L32)*M32/0.6)+((N32*O32)*P32/0.6)+((Q32*R32)*S32/0.6))))) -> M | U32: =IF(T32="M", "M", IF(T32>40, "YES", "NO")) -> M | X32: =IF(T32="M",0,IF(T32=0,0,IF(T32>0,1,0))) -> 0 | AL32: =IF(AN32=1,AX32,IF(AN32=2,AR32,IF(AN32=3,AS32,IF(AN32=4,AT32,IF(AN32=5,AU32,IF(AN32=6,AV32,IF(AN32=7,AW32))))))) -> FALSE | AM32: =IF(AO32=1,BF32,IF(AO32=2,AZ32,IF(AO32=3,BA32,IF(AO32=4,BB32,IF(AO32=5,BC32,IF(AO32=6,BD32,IF(AO32=7,BE32))))))) -> FALSE | AN32: =IF(D32="p1",AQ32,"no") -> no | AO32: =IF(D32="p2",AQ32,"no") -> no | AQ32: =WEEKDAY(C32) -> 1 | AR32: =AR31 -> M | AS32: =AS31 -> M | AT32: =AT31 -> 0.70833333 | AU32: =AU31 -> M | AV32: =AV31 -> M | AW32: =AW31 -> 0.70833333 | AX32: =AX31 -> M | AZ32: =AZ31 -> 0 | BA32: =BA31 -> 0 | BB32: =BB31 -> 0 | BC32: =BC31 -> 0 | BD32: =BD31 -> 0 | BE32: =BE31 -> 0 | BF32: =BF31 -> 0 | BI32: =IF(OR(E32="",F32="",G32=""),"M",1) -> M | BJ32: =IF(OR(H32="",I32="",J32=""),"M",1) -> M | BK32: =IF(OR(K32="",L32="",M32=""),"M",1) -> M | BL32: =IF(OR(N32="",O32="",P32=""),"M",1) -> M | BM32: =IF(OR(Q32="",R32="",S32=""),"M",1) -> M | BN32: =IF(AND(BI32="M",BJ32="M",BK32="M",BL32="M",BM32="M",D32=""),0,1) -> 0
... A63: -36 | B63: =B64-1 -> 45889 | C63: =C64-1 -> 45889 | T63: =IF(BN63=0,"M",IF(D63="p1",AL63,IF(D63="p2",AM63,IF(D63="A",0,((E63*F63)*G63/0.6)+((H63*I63)*J63/0.6)+((K63*L63)*M63/0.6)+((N63*O63)*P63/0.6)+((Q63*R63)*S63/0.6))))) -> M | U63: =IF(T63="M", "M", IF(T63>40, "YES", "NO")) -> M | X63: =IF(T63="M",0,IF(T63=0,0,IF(T63>0,1,0))) -> 0 | AL63: =IF(AN63=1,AX63,IF(AN63=2,AR63,IF(AN63=3,AS63,IF(AN63=4,AT63,IF(AN63=5,AU63,IF(AN63=6,AV63,IF(AN63=7,AW63))))))) -> FALSE | AM63: =IF(AO63=1,BF63,IF(AO63=2,AZ63,IF(AO63=3,BA63,IF(AO63=4,BB63,IF(AO63=5,BC63,IF(AO63=6,BD63,IF(AO63=7,BE63))))))) -> FALSE | AN63: =IF(D63="p1",AQ63,"no") -> no | AO63: =IF(D63="p2",AQ63,"no") -> no | AQ63: =WEEKDAY(C63) -> 4 | AR63: =AR62 -> M | AS63: =AS62 -> M | AT63: =AT62 -> 0.70833333 | AU63: =AU62 -> M | AV63: =AV62 -> M | AW63: =AW62 -> 0.70833333 | AX63: =AX62 -> M | AZ63: =AZ62 -> 0 | BA63: =BA62 -> 0 | BB63: =BB62 -> 0 | BC63: =BC62 -> 0 | BD63: =BD62 -> 0 | BE63: =BE62 -> 0 | BF63: =BF62 -> 0 | BI63: =IF(OR(E63="",F63="",G63=""),"M",1) -> M | BJ63: =IF(OR(H63="",I63="",J63=""),"M",1) -> M | BK63: =IF(OR(K63="",L63="",M63=""),"M",1) -> M | BL63: =IF(OR(N63="",O63="",P63=""),"M",1) -> M | BM63: =IF(OR(Q63="",R63="",S63=""),"M",1) -> M | BN63: =IF(AND(BI63="M",BJ63="M",BK63="M",BL63="M",BM63="M",D63=""),0,1) -> 0
A64: -35 | B64: =B65-1 -> 45890 | C64: =C65-1 -> 45890 | T64: =IF(BN64=0,"M",IF(D64="p1",AL64,IF(D64="p2",AM64,IF(D64="A",0,((E64*F64)*G64/0.6)+((H64*I64)*J64/0.6)+((K64*L64)*M64/0.6)+((N64*O64)*P64/0.6)+((Q64*R64)*S64/0.6))))) -> M | U64: =IF(T64="M", "M", IF(T64>40, "YES", "NO")) -> M | X64: =IF(T64="M",0,IF(T64=0,0,IF(T64>0,1,0))) -> 0 | Z64: =SUM(X9:X64) -> 0 | AA64: =IF(Z64=0,1,0) -> 1 | AL64: =IF(AN64=1,AX64,IF(AN64=2,AR64,IF(AN64=3,AS64,IF(AN64=4,AT64,IF(AN64=5,AU64,IF(AN64=6,AV64,IF(AN64=7,AW64))))))) -> FALSE | AM64: =IF(AO64=1,BF64,IF(AO64=2,AZ64,IF(AO64=3,BA64,IF(AO64=4,BB64,IF(AO64=5,BC64,IF(AO64=6,BD64,IF(AO64=7,BE64))))))) -> FALSE | AN64: =IF(D64="p1",AQ64,"no") -> no | AO64: =IF(D64="p2",AQ64,"no") -> no | AQ64: =WEEKDAY(C64) -> 5 | AR64: =AR63 -> M | AS64: =AS63 -> M | AT64: =AT63 -> 0.70833333 | AU64: =AU63 -> M | AV64: =AV63 -> M | AW64: =AW63 -> 0.70833333 | AX64: =AX63 -> M | AZ64: =AZ63 -> 0 | BA64: =BA63 -> 0 | BB64: =BB63 -> 0 | BC64: =BC63 -> 0 | BD64: =BD63 -> 0 | BE64: =BE63 -> 0 | BF64: =BF63 -> 0 | BI64: =IF(OR(E64="",F64="",G64=""),"M",1) -> M | BJ64: =IF(OR(H64="",I64="",J64=""),"M",1) -> M | BK64: =IF(OR(K64="",L64="",M64=""),"M",1) -> M | BL64: =IF(OR(N64="",O64="",P64=""),"M",1) -> M | BM64: =IF(OR(Q64="",R64="",S64=""),"M",1) -> M | BN64: =IF(AND(BI64="M",BJ64="M",BK64="M",BL64="M",BM64="M",D64=""),0,1) -> 0
A65: -34 | B65: =B66-1 -> 45891 | C65: =C66-1 -> 45891 | T65: =IF(BN65=0,"M",IF(D65="p1",AL65,IF(D65="p2",AM65,IF(D65="A",0,((E65*F65)*G65/0.6)+((H65*I65)*J65/0.6)+((K65*L65)*M65/0.6)+((N65*O65)*P65/0.6)+((Q65*R65)*S65/0.6))))) -> M | U65: =IF(T65="M", "M", IF(T65>40, "YES", "NO")) -> M | X65: =IF(T65="M",0,IF(T65=0,0,IF(T65>0,1,0))) -> 0 | Z65: =SUM(X10:X65) -> 0 | AA65: =IF(Z65=0,1,0) -> 1 | AL65: =IF(AN65=1,AX65,IF(AN65=2,AR65,IF(AN65=3,AS65,IF(AN65=4,AT65,IF(AN65=5,AU65,IF(AN65=6,AV65,IF(AN65=7,AW65))))))) -> FALSE | AM65: =IF(AO65=1,BF65,IF(AO65=2,AZ65,IF(AO65=3,BA65,IF(AO65=4,BB65,IF(AO65=5,BC65,IF(AO65=6,BD65,IF(AO65=7,BE65))))))) -> FALSE | AN65: =IF(D65="p1",AQ65,"no") -> no | AO65: =IF(D65="p2",AQ65,"no") -> no | AQ65: =WEEKDAY(C65) -> 6 | AR65: =AR64 -> M | AS65: =AS64 -> M | AT65: =AT64 -> 0.70833333 | AU65: =AU64 -> M | AV65: =AV64 -> M | AW65: =AW64 -> 0.70833333 | AX65: =AX64 -> M | AZ65: =AZ64 -> 0 | BA65: =BA64 -> 0 | BB65: =BB64 -> 0 | BC65: =BC64 -> 0 | BD65: =BD64 -> 0 | BE65: =BE64 -> 0 | BF65: =BF64 -> 0 | BI65: =IF(OR(E65="",F65="",G65=""),"M",1) -> M | BJ65: =IF(OR(H65="",I65="",J65=""),"M",1) -> M | BK65: =IF(OR(K65="",L65="",M65=""),"M",1) -> M | BL65: =IF(OR(N65="",O65="",P65=""),"M",1) -> M | BM65: =IF(OR(Q65="",R65="",S65=""),"M",1) -> M | BN65: =IF(AND(BI65="M",BJ65="M",BK65="M",BL65="M",BM65="M",D65=""),0,1) -> 0
A66: -33 | B66: =B67-1 -> 45892 | C66: =C67-1 -> 45892 | T66: =IF(BN66=0,"M",IF(D66="p1",AL66,IF(D66="p2",AM66,IF(D66="A",0,((E66*F66)*G66/0.6)+((H66*I66)*J66/0.6)+((K66*L66)*M66/0.6)+((N66*O66)*P66/0.6)+((Q66*R66)*S66/0.6))))) -> M | U66: =IF(T66="M", "M", IF(T66>40, "YES", "NO")) -> M | X66: =IF(T66="M",0,IF(T66=0,0,IF(T66>0,1,0))) -> 0 | Z66: =SUM(X11:X66) -> 0 | AA66: =IF(Z66=0,1,0) -> 1 | AL66: =IF(AN66=1,AX66,IF(AN66=2,AR66,IF(AN66=3,AS66,IF(AN66=4,AT66,IF(AN66=5,AU66,IF(AN66=6,AV66,IF(AN66=7,AW66))))))) -> FALSE | AM66: =IF(AO66=1,BF66,IF(AO66=2,AZ66,IF(AO66=3,BA66,IF(AO66=4,BB66,IF(AO66=5,BC66,IF(AO66=6,BD66,IF(AO66=7,BE66))))))) -> FALSE | AN66: =IF(D66="p1",AQ66,"no") -> no | AO66: =IF(D66="p2",AQ66,"no") -> no | AQ66: =WEEKDAY(C66) -> 7 | AR66: =AR65 -> M | AS66: =AS65 -> M | AT66: =AT65 -> 0.70833333 | AU66: =AU65 -> M | AV66: =AV65 -> M | AW66: =AW65 -> 0.70833333 | AX66: =AX65 -> M | AZ66: =AZ65 -> 0 | BA66: =BA65 -> 0 | BB66: =BB65 -> 0 | BC66: =BC65 -> 0 | BD66: =BD65 -> 0 | BE66: =BE65 -> 0 | BF66: =BF65 -> 0 | BI66: =IF(OR(E66="",F66="",G66=""),"M",1) -> M | BJ66: =IF(OR(H66="",I66="",J66=""),"M",1) -> M | BK66: =IF(OR(K66="",L66="",M66=""),"M",1) -> M | BL66: =IF(OR(N66="",O66="",P66=""),"M",1) -> M | BM66: =IF(OR(Q66="",R66="",S66=""),"M",1) -> M | BN66: =IF(AND(BI66="M",BJ66="M",BK66="M",BL66="M",BM66="M",D66=""),0,1) -> 0
A67: -32 | B67: =B68-1 -> 45893 | C67: =C68-1 -> 45893 | T67: =IF(BN67=0,"M",IF(D67="p1",AL67,IF(D67="p2",AM67,IF(D67="A",0,((E67*F67)*G67/0.6)+((H67*I67)*J67/0.6)+((K67*L67)*M67/0.6)+((N67*O67)*P67/0.6)+((Q67*R67)*S67/0.6))))) -> M | U67: =IF(T67="M", "M", IF(T67>40, "YES", "NO")) -> M | X67: =IF(T67="M",0,IF(T67=0,0,IF(T67>0,1,0))) -> 0 | Z67: =SUM(X12:X67) -> 0 | AA67: =IF(Z67=0,1,0) -> 1 | AL67: =IF(AN67=1,AX67,IF(AN67=2,AR67,IF(AN67=3,AS67,IF(AN67=4,AT67,IF(AN67=5,AU67,IF(AN67=6,AV67,IF(AN67=7,AW67))))))) -> FALSE | AM67: =IF(AO67=1,BF67,IF(AO67=2,AZ67,IF(AO67=3,BA67,IF(AO67=4,BB67,IF(AO67=5,BC67,IF(AO67=6,BD67,IF(AO67=7,BE67))))))) -> FALSE | AN67: =IF(D67="p1",AQ67,"no") -> no | AO67: =IF(D67="p2",AQ67,"no") -> no | AQ67: =WEEKDAY(C67) -> 1 | AR67: =AR66 -> M | AS67: =AS66 -> M | AT67: =AT66 -> 0.70833333 | AU67: =AU66 -> M | AV67: =AV66 -> M | AW67: =AW66 -> 0.70833333 | AX67: =AX66 -> M | AZ67: =AZ66 -> 0 | BA67: =BA66 -> 0 | BB67: =BB66 -> 0 | BC67: =BC66 -> 0 | BD67: =BD66 -> 0 | BE67: =BE66 -> 0 | BF67: =BF66 -> 0 | BI67: =IF(OR(E67="",F67="",G67=""),"M",1) -> M | BJ67: =IF(OR(H67="",I67="",J67=""),"M",1) -> M | BK67: =IF(OR(K67="",L67="",M67=""),"M",1) -> M | BL67: =IF(OR(N67="",O67="",P67=""),"M",1) -> M | BM67: =IF(OR(Q67="",R67="",S67=""),"M",1) -> M | BN67: =IF(AND(BI67="M",BJ67="M",BK67="M",BL67="M",BM67="M",D67=""),0,1) -> 0
A68: -31 | B68: =B69-1 -> 45894 | C68: =C69-1 -> 45894 | T68: =IF(BN68=0,"M",IF(D68="p1",AL68,IF(D68="p2",AM68,IF(D68="A",0,((E68*F68)*G68/0.6)+((H68*I68)*J68/0.6)+((K68*L68)*M68/0.6)+((N68*O68)*P68/0.6)+((Q68*R68)*S68/0.6))))) -> M | U68: =IF(T68="M", "M", IF(T68>40, "YES", "NO")) -> M | X68: =IF(T68="M",0,IF(T68=0,0,IF(T68>0,1,0))) -> 0 | Z68: =SUM(X13:X68) -> 0 | AA68: =IF(Z68=0,1,0) -> 1 | AL68: =IF(AN68=1,AX68,IF(AN68=2,AR68,IF(AN68=3,AS68,IF(AN68=4,AT68,IF(AN68=5,AU68,IF(AN68=6,AV68,IF(AN68=7,AW68))))))) -> FALSE | AM68: =IF(AO68=1,BF68,IF(AO68=2,AZ68,IF(AO68=3,BA68,IF(AO68=4,BB68,IF(AO68=5,BC68,IF(AO68=6,BD68,IF(AO68=7,BE68))))))) -> FALSE | AN68: =IF(D68="p1",AQ68,"no") -> no | AO68: =IF(D68="p2",AQ68,"no") -> no | AQ68: =WEEKDAY(C68) -> 2 | AR68: =AR67 -> M | AS68: =AS67 -> M | AT68: =AT67 -> 0.70833333 | AU68: =AU67 -> M | AV68: =AV67 -> M | AW68: =AW67 -> 0.70833333 | AX68: =AX67 -> M | AZ68: =AZ67 -> 0 | BA68: =BA67 -> 0 | BB68: =BB67 -> 0 | BC68: =BC67 -> 0 | BD68: =BD67 -> 0 | BE68: =BE67 -> 0 | BF68: =BF67 -> 0 | BI68: =IF(OR(E68="",F68="",G68=""),"M",1) -> M | BJ68: =IF(OR(H68="",I68="",J68=""),"M",1) -> M | BK68: =IF(OR(K68="",L68="",M68=""),"M",1) -> M | BL68: =IF(OR(N68="",O68="",P68=""),"M",1) -> M | BM68: =IF(OR(Q68="",R68="",S68=""),"M",1) -> M | BN68: =IF(AND(BI68="M",BJ68="M",BK68="M",BL68="M",BM68="M",D68=""),0,1) -> 0
A69: -30 | B69: =B70-1 -> 45895 | C69: =C70-1 -> 45895 | T69: =IF(BN69=0,"M",IF(D69="p1",AL69,IF(D69="p2",AM69,IF(D69="A",0,((E69*F69)*G69/0.6)+((H69*I69)*J69/0.6)+((K69*L69)*M69/0.6)+((N69*O69)*P69/0.6)+((Q69*R69)*S69/0.6))))) -> M | U69: =IF(T69="M", "M", IF(T69>40, "YES", "NO")) -> M | X69: =IF(T69="M",0,IF(T69=0,0,IF(T69>0,1,0))) -> 0 | Z69: =SUM(X14:X69) -> 0 | AA69: =IF(Z69=0,1,0) -> 1 | AL69: =IF(AN69=1,AX69,IF(AN69=2,AR69,IF(AN69=3,AS69,IF(AN69=4,AT69,IF(AN69=5,AU69,IF(AN69=6,AV69,IF(AN69=7,AW69))))))) -> FALSE | AM69: =IF(AO69=1,BF69,IF(AO69=2,AZ69,IF(AO69=3,BA69,IF(AO69=4,BB69,IF(AO69=5,BC69,IF(AO69=6,BD69,IF(AO69=7,BE69))))))) -> FALSE | AN69: =IF(D69="p1",AQ69,"no") -> no | AO69: =IF(D69="p2",AQ69,"no") -> no | AQ69: =WEEKDAY(C69) -> 3 | AR69: =AR68 -> M | AS69: =AS68 -> M | AT69: =AT68 -> 0.70833333 | AU69: =AU68 -> M | AV69: =AV68 -> M | AW69: =AW68 -> 0.70833333 | AX69: =AX68 -> M | AZ69: =AZ68 -> 0 | BA69: =BA68 -> 0 | BB69: =BB68 -> 0 | BC69: =BC68 -> 0 | BD69: =BD68 -> 0 | BE69: =BE68 -> 0 | BF69: =BF68 -> 0 | BI69: =IF(OR(E69="",F69="",G69=""),"M",1) -> M | BJ69: =IF(OR(H69="",I69="",J69=""),"M",1) -> M | BK69: =IF(OR(K69="",L69="",M69=""),"M",1) -> M | BL69: =IF(OR(N69="",O69="",P69=""),"M",1) -> M | BM69: =IF(OR(Q69="",R69="",S69=""),"M",1) -> M | BN69: =IF(AND(BI69="M",BJ69="M",BK69="M",BL69="M",BM69="M",D69=""),0,1) -> 0
A70: -29 | B70: =B71-1 -> 45896 | C70: =C71-1 -> 45896 | T70: =IF(BN70=0,"M",IF(D70="p1",AL70,IF(D70="p2",AM70,IF(D70="A",0,((E70*F70)*G70/0.6)+((H70*I70)*J70/0.6)+((K70*L70)*M70/0.6)+((N70*O70)*P70/0.6)+((Q70*R70)*S70/0.6))))) -> M | U70: =IF(T70="M", "M", IF(T70>40, "YES", "NO")) -> M | X70: =IF(T70="M",0,IF(T70=0,0,IF(T70>0,1,0))) -> 0 | Z70: =SUM(X15:X70) -> 0 | AA70: =IF(Z70=0,1,0) -> 1 | AL70: =IF(AN70=1,AX70,IF(AN70=2,AR70,IF(AN70=3,AS70,IF(AN70=4,AT70,IF(AN70=5,AU70,IF(AN70=6,AV70,IF(AN70=7,AW70))))))) -> FALSE | AM70: =IF(AO70=1,BF70,IF(AO70=2,AZ70,IF(AO70=3,BA70,IF(AO70=4,BB70,IF(AO70=5,BC70,IF(AO70=6,BD70,IF(AO70=7,BE70))))))) -> FALSE | AN70: =IF(D70="p1",AQ70,"no") -> no | AO70: =IF(D70="p2",AQ70,"no") -> no | AQ70: =WEEKDAY(C70) -> 4 | AR70: =AR69 -> M | AS70: =AS69 -> M | AT70: =AT69 -> 0.70833333 | AU70: =AU69 -> M | AV70: =AV69 -> M | AW70: =AW69 -> 0.70833333 | AX70: =AX69 -> M | AZ70: =AZ69 -> 0 | BA70: =BA69 -> 0 | BB70: =BB69 -> 0 | BC70: =BC69 -> 0 | BD70: =BD69 -> 0 | BE70: =BE69 -> 0 | BF70: =BF69 -> 0 | BI70: =IF(OR(E70="",F70="",G70=""),"M",1) -> M | BJ70: =IF(OR(H70="",I70="",J70=""),"M",1) -> M | BK70: =IF(OR(K70="",L70="",M70=""),"M",1) -> M | BL70: =IF(OR(N70="",O70="",P70=""),"M",1) -> M | BM70: =IF(OR(Q70="",R70="",S70=""),"M",1) -> M | BN70: =IF(AND(BI70="M",BJ70="M",BK70="M",BL70="M",BM70="M",D70=""),0,1) -> 0
A71: -28 | B71: =B72-1 -> 45897 | C71: =C72-1 -> 45897 | T71: =IF(BN71=0,"M",IF(D71="p1",AL71,IF(D71="p2",AM71,IF(D71="A",0,((E71*F71)*G71/0.6)+((H71*I71)*J71/0.6)+((K71*L71)*M71/0.6)+((N71*O71)*P71/0.6)+((Q71*R71)*S71/0.6))))) -> M | U71: =IF(T71="M", "M", IF(T71>40, "YES", "NO")) -> M | X71: =IF(T71="M",0,IF(T71=0,0,IF(T71>0,1,0))) -> 0 | Z71: =SUM(X16:X71) -> 0 | AA71: =IF(Z71=0,1,0) -> 1 | AL71: =IF(AN71=1,AX71,IF(AN71=2,AR71,IF(AN71=3,AS71,IF(AN71=4,AT71,IF(AN71=5,AU71,IF(AN71=6,AV71,IF(AN71=7,AW71))))))) -> FALSE | AM71: =IF(AO71=1,BF71,IF(AO71=2,AZ71,IF(AO71=3,BA71,IF(AO71=4,BB71,IF(AO71=5,BC71,IF(AO71=6,BD71,IF(AO71=7,BE71))))))) -> FALSE | AN71: =IF(D71="p1",AQ71,"no") -> no | AO71: =IF(D71="p2",AQ71,"no") -> no | AQ71: =WEEKDAY(C71) -> 5 | AR71: =AR70 -> M | AS71: =AS70 -> M | AT71: =AT70 -> 0.70833333 | AU71: =AU70 -> M | AV71: =AV70 -> M | AW71: =AW70 -> 0.70833333 | AX71: =AX70 -> M | AZ71: =AZ70 -> 0 | BA71: =BA70 -> 0 | BB71: =BB70 -> 0 | BC71: =BC70 -> 0 | BD71: =BD70 -> 0 | BE71: =BE70 -> 0 | BF71: =BF70 -> 0 | BI71: =IF(OR(E71="",F71="",G71=""),"M",1) -> M | BJ71: =IF(OR(H71="",I71="",J71=""),"M",1) -> M | BK71: =IF(OR(K71="",L71="",M71=""),"M",1) -> M | BL71: =IF(OR(N71="",O71="",P71=""),"M",1) -> M | BM71: =IF(OR(Q71="",R71="",S71=""),"M",1) -> M | BN71: =IF(AND(BI71="M",BJ71="M",BK71="M",BL71="M",BM71="M",D71=""),0,1) -> 0
...

Sheet P1 Chart
B1: Pattern Chart 1 (P1) | S1: Check Missing Values
B2: Beverage Type #1 | E2: Beverage Type #2 | H2: Beverage Type #3 | K2: Beverage Type #4 | N2: BeverageType #5
A3: Day | B3: # of drinks | C3: # of oz per drink | D3: Conc. Of ETOH | E3: # of drinks | F3: # of oz per drink | G3: Conc. Of ETOH | H3: # of drinks | I3: # of oz per drink | J3: Conc. Of ETOH | K3: # of drinks | L3: # of oz per drink | M3: Conc. Of ETOH | N3: # of drinks | O3: # of oz per drink | P3: Conc. Of ETOH | Q3: Total SDUs
A4: Monday | B4: 0 | Q4: =IF(X4=0,"M",((B4*C4)*D4/0.6) + ((E4*F4)*G4/0.6) +((H4*I4)*J4/0.6) +((K4*L4)*M4/0.6) + ((N4*O4)*P4/0.6)) -> M | S4: =IF(OR(B4="",C4="",D4=""),"M",1) -> M | T4: =IF(OR(E4="",F4="",G4=""),"M",1) -> M | U4: =IF(OR(H4="",I4="",J4=""),"M",1) -> M | V4: =IF(OR(K4="",L4="",M4=""),"M",1) -> M | W4: =IF(OR(N4="",O4="",P4=""),"M",1) -> M | X4: =IF(AND(S4="M",T4="M",U4="M",V4="M",W4="M"),0,1) -> 0
A5: Tuesday | B5: 0 | Q5: =IF(X5=0,"M",((B5*C5)*D5/0.6) + ((E5*F5)*G5/0.6) +((H5*I5)*J5/0.6) +((K5*L5)*M5/0.6) + ((N5*O5)*P5/0.6)) -> M | S5: =IF(OR(B5="",C5="",D5=""),"M",1) -> M | T5: =IF(OR(E5="",F5="",G5=""),"M",1) -> M | U5: =IF(OR(H5="",I5="",J5=""),"M",1) -> M | V5: =IF(OR(K5="",L5="",M5=""),"M",1) -> M | W5: =IF(OR(N5="",O5="",P5=""),"M",1) -> M | X5: =IF(AND(S5="M",T5="M",U5="M",V5="M",W5="M"),0,1) -> 0
A6: Wednesday | B6: 1 | C6: 8.5 | D6: 0.05 | Q6: =IF(X6=0,"M",((B6*C6)*D6/0.6) + ((E6*F6)*G6/0.6) +((H6*I6)*J6/0.6) +((K6*L6)*M6/0.6) + ((N6*O6)*P6/0.6)) -> 0.70833333 | S6: =IF(OR(B6="",C6="",D6=""),"M",1) -> 1 | T6: =IF(OR(E6="",F6="",G6=""),"M",1) -> M | U6: =IF(OR(H6="",I6="",J6=""),"M",1) -> M | V6: =IF(OR(K6="",L6="",M6=""),"M",1) -> M | W6: =IF(OR(N6="",O6="",P6=""),"M",1) -> M | X6: =IF(AND(S6="M",T6="M",U6="M",V6="M",W6="M"),0,1) -> 1
A7: Thursday | B7: 0 | Q7: =IF(X7=0,"M",((B7*C7)*D7/0.6) + ((E7*F7)*G7/0.6) +((H7*I7)*J7/0.6) +((K7*L7)*M7/0.6) + ((N7*O7)*P7/0.6)) -> M | S7: =IF(OR(B7="",C7="",D7=""),"M",1) -> M | T7: =IF(OR(E7="",F7="",G7=""),"M",1) -> M | U7: =IF(OR(H7="",I7="",J7=""),"M",1) -> M | V7: =IF(OR(K7="",L7="",M7=""),"M",1) -> M | W7: =IF(OR(N7="",O7="",P7=""),"M",1) -> M | X7: =IF(AND(S7="M",T7="M",U7="M",V7="M",W7="M"),0,1) -> 0
A8: Friday | B8: 0 | Q8: =IF(X8=0,"M",((B8*C8)*D8/0.6) + ((E8*F8)*G8/0.6) +((H8*I8)*J8/0.6) +((K8*L8)*M8/0.6) + ((N8*O8)*P8/0.6)) -> M | S8: =IF(OR(B8="",C8="",D8=""),"M",1) -> M | T8: =IF(OR(E8="",F8="",G8=""),"M",1) -> M | U8: =IF(OR(H8="",I8="",J8=""),"M",1) -> M | V8: =IF(OR(K8="",L8="",M8=""),"M",1) -> M | W8: =IF(OR(N8="",O8="",P8=""),"M",1) -> M | X8: =IF(AND(S8="M",T8="M",U8="M",V8="M",W8="M"),0,1) -> 0
A9: Saturday | B9: 1 | C9: 8.5 | D9: 0.05 | Q9: =IF(X9=0,"M",((B9*C9)*D9/0.6) + ((E9*F9)*G9/0.6) +((H9*I9)*J9/0.6) +((K9*L9)*M9/0.6) + ((N9*O9)*P9/0.6)) -> 0.70833333 | S9: =IF(OR(B9="",C9="",D9=""),"M",1) -> 1 | T9: =IF(OR(E9="",F9="",G9=""),"M",1) -> M | U9: =IF(OR(H9="",I9="",J9=""),"M",1) -> M | V9: =IF(OR(K9="",L9="",M9=""),"M",1) -> M | W9: =IF(OR(N9="",O9="",P9=""),"M",1) -> M | X9: =IF(AND(S9="M",T9="M",U9="M",V9="M",W9="M"),0,1) -> 1
A10: Sunday | Q10: =IF(X10=0,"M",((B10*C10)*D10/0.6) + ((E10*F10)*G10/0.6) +((H10*I10)*J10/0.6) +((K10*L10)*M10/0.6) + ((N10*O10)*P10/0.6)) -> M | S10: =IF(OR(B10="",C10="",D10=""),"M",1) -> M | T10: =IF(OR(E10="",F10="",G10=""),"M",1) -> M | U10: =IF(OR(H10="",I10="",J10=""),"M",1) -> M | V10: =IF(OR(K10="",L10="",M10=""),"M",1) -> M | W10: =IF(OR(N10="",O10="",P10=""),"M",1) -> M | X10: =IF(AND(S10="M",T10="M",U10="M",V10="M",W10="M"),0,1) -> 0
B14: Pattern Chart 2 (P2)
B15: Beverage Type #1 | E15: Beverage #2 | H15: Beverage Type #3 | K15: Beverage Type #4 | N15: BeverageType #5
A16: Day | B16: # of drinks | C16: # of oz per drink | D16: Conc. Of ETOH | E16: # of drinks | F16: # of oz per drink | G16: Conc. Of ETOH | H16: # of drinks | I16: # of oz per drink | J16: Conc. Of ETOH | K16: # of drinks | L16: # of oz per drink | M16: Conc. Of ETOH | N16: # of drinks | O16: # of oz per drink | P16: Conc. Of ETOH | Q16: Total SDUs
A17: Monday | Q17: =((B17*C17)*D17/0.5) + ((E17*F17)*G17/0.5) +((H17*I17)*J17/0.5) +((K17*L17)*M17/0.5) + ((N17*O17)*P17/0.5) -> 0
A18: Tuesday | Q18: =((B18*C18)*D18/0.5) + ((E18*F18)*G18/0.5) +((H18*I18)*J18/0.5) +((K18*L18)*M18/0.5) + ((N18*O18)*P18/0.5) -> 0
A19: Wednesday | Q19: =((B19*C19)*D19/0.5) + ((E19*F19)*G19/0.5) +((H19*I19)*J19/0.5) +((K19*L19)*M19/0.5) + ((N19*O19)*P19/0.5) -> 0
A20: Thursday | Q20: =((B20*C20)*D20/0.5) + ((E20*F20)*G20/0.5) +((H20*I20)*J20/0.5) +((K20*L20)*M20/0.5) + ((N20*O20)*P20/0.5) -> 0
A21: Friday | Q21: =((B21*C21)*D21/0.5) + ((E21*F21)*G21/0.5) +((H21*I21)*J21/0.5) +((K21*L21)*M21/0.5) + ((N21*O21)*P21/0.5) -> 0
A22: Saturday | Q22: =((B22*C22)*D22/0.5) + ((E22*F22)*G22/0.5) +((H22*I22)*J22/0.5) +((K22*L22)*M22/0.5) + ((N22*O22)*P22/0.5) -> 0
A23: Sunday | Q23: =((B23*C23)*D23/0.5) + ((E23*F23)*G23/0.5) +((H23*I23)*J23/0.5) +((K23*L23)*M23/0.5) + ((N23*O23)*P23/0.5) -> 0

Sheet Eligibility
B2: TLFB ELIGIBILITY INFORMATION
D5: SUBJECT ID: | E5: =Calculator!H4 -> 1
E6: =IF(Calculator!H5="","",IF(Calculator!H5=1,"MALE","FEMALE")) -> FEMALE
B8: =Calculator!BQ9 -> There are 84 days of missing drinking data in 90-day screening assessment period. Missing Baseline screening data must be collected prior to randomization.
B12: Average number of drinks per day during the 90-day screening period (total drinks consumed/90) | C12: =IF(Calculator!BQ16>0,"MISSING DATA",Calculator!AF8) -> MISSING DATA
B13: Total number of abstinent days in the 90-day screening period | C13: =IF(Calculator!BQ16>0,"MISSING DATA",90-Calculator!X104) -> MISSING DATA
B14: Does the participant have any periods during screening with 8 weeks on consecutive abstinence? | C14: =IF(Calculator!BQ16>0,"MISSSING DATA",IF(Calculator!AB98>0,"Yes","No")) -> MISSSING DATA

Sheet Dup Calc
A1: REMINDER: CUT & PASTE WILL CORRUPT FORMULAS ALWAYS USE COPY & PASTE | J1: Please use calculator to convert Drinks to Standard Drinking Units
E3: Input Subject ID and Sex | K3: Input date below | W3: Days -1 to -90 prior ICF:
A4: Staff Initials (calculation) | E4: Subject ID | K4: Date of Screening | W4: Days between ICF and RAND: | AB4: =O5-O4 -> 0
E5: Study Visit Name | Q5: =O4+45 -> 45
AQ6: Day of the week Pattern Chart 1 | AY6: Day of the week Pattern Chart 2
E7: Beverage type #1 | H7: Beverage type #2 | K7: Beverage type #3 | N7: Beverage type #4 | Q7: Beverage type #5 | AQ7: 2 | AR7: 3 | AS7: 4 | AT7: 5 | AU7: 6 | AV7: 7 | AW7: 1 | AY7: 2 | AZ7: 3 | BA7: 4 | BB7: 5 | BC7: 6 | BD7: 7 | BE7: 1 | BH7: Check for Missing data
A8: Drinking Day | B8: Day | C8: Date | D8: Pattern P1 A BLANK | E8: # of drinks | F8: # of oz per drink | G8: Conc. Of ETOH (ABV) | H8: # of drinks | I8: # of oz per drink | J8: Conc. Of ETOH (ABV) | K8: # of drinks | L8: # of oz per drink | M8: Conc. Of ETOH (ABV) | N8: # of drinks | O8: # of oz per drink | P8: Conc. Of ETOH (ABV) | Q8: # of drinks | R8: # of oz per drink | S8: Conc. Of ETOH (ABV) | T8: Total SDUs | U8: Validity Check | W8: Is drinking data valid | AD8: Average drinks per day in screening | AE8: =T104/W104 -> 0 | AG8: =CONCATENATE("The subject has consumed an average of ",AE8," drinks per day in the 90 days prior to consent") -> The subject has consumed an average of 0 drinks per day in the 90 days prior to consent | AK8: P1 Value | AL8: P2 Value | AM8: If P1 is True = day of week | AN8: If P2 is True = day of week | AP8: Coded Day of week | AQ8: P1 MON | AR8: P1 TUES | AS8: P1 WED | AT8: P1 THR | AU8: P1 FRI | AV8: P1 SAT | AW8: P1 SUN | AY8: P2 MON | AZ8: P2 TUES | BA8: P2 WED | BB8: P2 THR | BC8: P2 FRI | BD8: P2 SAT | BE8: P2 SUN | BH8: BEV1 | BI8: BEV2 | BJ8: BEV3 | BK8: BEV4 | BL8: BEV5 | BM8: Valid data for day (=1) no valid data (=0) | BP8: Text Strings
A9: -90 | B9: =B10-1 -> -90 | C9: =C10-1 -> -90 | T9: =IF(BM9=0,"M",IF(D9="p1",AK9,IF(D9="p2",AL9,IF(D9="A",0,((E9*F9)*G9/0.6)+((H9*I9)*J9/0.6)+((K9*L9)*M9/0.6)+((N9*O9)*P9/0.6)+((Q9*R9)*S9/0.6))))) -> M | U9: =IF(T9=Calculator!T9,"VALID","ERROR") -> ERROR | W9: =IF(U9="VALID",0,IF(U9="ERROR",1,0)) -> 1 | AK9: =IF(AM9=1,AW9,IF(AM9=2,AQ9,IF(AM9=3,AR9,IF(AM9=4,AS9,IF(AM9=5,AT9,IF(AM9=6,AU9,IF(AM9=7,AV9))))))) -> FALSE | AL9: =IF(AN9=1,BE9,IF(AN9=2,AY9,IF(AN9=3,AZ9,IF(AN9=4,BA9,IF(AN9=5,BB9,IF(AN9=6,BC9,IF(AN9=7,BD9))))))) -> FALSE | AM9: =IF(D9="p1",AP9,"no") -> no | AN9: =IF(D9="p2",AP9,"no") -> no | AP9: =WEEKDAY(C9) -> #NUM! | AQ9: ='Dup P1 Chart'!Q4 -> M | AR9: ='Dup P1 Chart'!Q5 -> M | AS9: ='Dup P1 Chart'!Q6 -> M | AT9: ='Dup P1 Chart'!Q7 -> M | AU9: ='Dup P1 Chart'!Q8 -> M | AV9: ='Dup P1 Chart'!Q9 -> M | AW9: ='Dup P1 Chart'!Q10 -> M | AY9: ='P1 Chart'!Q17 -> 0 | AZ9: ='P1 Chart'!Q18 -> 0 | BA9: ='P1 Chart'!Q19 -> 0 | BB9: ='P1 Chart'!Q20 -> 0 | BC9: ='P1 Chart'!Q21 -> 0 | BD9: ='P1 Chart'!Q22 -> 0 | BE9: ='P1 Chart'!Q23 -> 0 | BH9: =IF(OR(E9="",F9="",G9=""),"M",1) -> M | BI9: =IF(OR(H9="",I9="",J9=""),"M",1) -> M | BJ9: =IF(OR(K9="",L9="",M9=""),"M",1) -> M | BK9: =IF(OR(N9="",O9="",P9=""),"M",1) -> M | BL9: =IF(OR(Q9="",R9="",S9=""),"M",1) -> M | BM9: =IF(AND(BH9="M",BI9="M",BJ9="M",BK9="M",BL9="M",D9=""),0,1) -> 0 | BN9: =SUM(BM9:BM98) -> 0 | BP9: =IF(BN9=28,BP19,BP13) -> There are 90 days of missing drinking data in 90-day screening assessment period. Missing Baseline screening data must be collected prior to randomization.
A10: -89 | B10: =B11-1 -> -89 | C10: =C11-1 -> -89 | T10: =IF(BM10=0,"M",IF(D10="p1",AK10,IF(D10="p2",AL10,IF(D10="A",0,((E10*F10)*G10/0.6)+((H10*I10)*J10/0.6)+((K10*L10)*M10/0.6)+((N10*O10)*P10/0.6)+((Q10*R10)*S10/0.6))))) -> M | U10: =IF(T10=Calculator!T10,"VALID","ERROR") -> ERROR | W10: =IF(U10="VALID",0,IF(U10="ERROR",1,0)) -> 1 | AK10: =IF(AM10=1,AW10,IF(AM10=2,AQ10,IF(AM10=3,AR10,IF(AM10=4,AS10,IF(AM10=5,AT10,IF(AM10=6,AU10,IF(AM10=7,AV10))))))) -> FALSE | AL10: =IF(AN10=1,BE10,IF(AN10=2,AY10,IF(AN10=3,AZ10,IF(AN10=4,BA10,IF(AN10=5,BB10,IF(AN10=6,BC10,IF(AN10=7,BD10))))))) -> FALSE | AM10: =IF(D10="p1",AP10,"no") -> no | AN10: =IF(D10="p2",AP10,"no") -> no | AP10: =WEEKDAY(C10) -> #NUM! | AQ10: =AQ9 -> M | AR10: =AR9 -> M | AS10: =AS9 -> M | AT10: =AT9 -> M | AU10: =AU9 -> M | AV10: =AV9 -> M | AW10: =AW9 -> M | AY10: =AY9 -> 0 | AZ10: =AZ9 -> 0 | BA10: =BA9 -> 0 | BB10: =BB9 -> 0 | BC10: =BC9 -> 0 | BD10: =BD9 -> 0 | BE10: =BE9 -> 0 | BH10: =IF(OR(E10="",F10="",G10=""),"M",1) -> M | BI10: =IF(OR(H10="",I10="",J10=""),"M",1) -> M | BJ10: =IF(OR(K10="",L10="",M10=""),"M",1) -> M | BK10: =IF(OR(N10="",O10="",P10=""),"M",1) -> M | BL10: =IF(OR(Q10="",R10="",S10=""),"M",1) -> M | BM10: =IF(AND(BH10="M",BI10="M",BJ10="M",BK10="M",BL10="M",D10=""),0,1) -> 0 | BN10: 90
A11: -88 | B11: =B12-1 -> -88 | C11: =C12-1 -> -88 | T11: =IF(BM11=0,"M",IF(D11="p1",AK11,IF(D11="p2",AL11,IF(D11="A",0,((E11*F11)*G11/0.6)+((H11*I11)*J11/0.6)+((K11*L11)*M11/0.6)+((N11*O11)*P11/0.6)+((Q11*R11)*S11/0.6))))) -> M | U11: =IF(T11=Calculator!T11,"VALID","ERROR") -> ERROR | W11: =IF(U11="VALID",0,IF(U11="ERROR",1,0)) -> 1 | AK11: =IF(AM11=1,AW11,IF(AM11=2,AQ11,IF(AM11=3,AR11,IF(AM11=4,AS11,IF(AM11=5,AT11,IF(AM11=6,AU11,IF(AM11=7,AV11))))))) -> FALSE | AL11: =IF(AN11=1,BE11,IF(AN11=2,AY11,IF(AN11=3,AZ11,IF(AN11=4,BA11,IF(AN11=5,BB11,IF(AN11=6,BC11,IF(AN11=7,BD11))))))) -> FALSE | AM11: =IF(D11="p1",AP11,"no") -> no | AN11: =IF(D11="p2",AP11,"no") -> no | AP11: =WEEKDAY(C11) -> #NUM! | AQ11: =AQ10 -> M | AR11: =AR10 -> M | AS11: =AS10 -> M | AT11: =AT10 -> M | AU11: =AU10 -> M | AV11: =AV10 -> M | AW11: =AW10 -> M | AY11: =AY10 -> 0 | AZ11: =AZ10 -> 0 | BA11: =BA10 -> 0 | BB11: =BB10 -> 0 | BC11: =BC10 -> 0 | BD11: =BD10 -> 0 | BE11: =BE10 -> 0 | BH11: =IF(OR(E11="",F11="",G11=""),"M",1) -> M | BI11: =IF(OR(H11="",I11="",J11=""),"M",1) -> M | BJ11: =IF(OR(K11="",L11="",M11=""),"M",1) -> M | BK11: =IF(OR(N11="",O11="",P11=""),"M",1) -> M | BL11: =IF(OR(Q11="",R11="",S11=""),"M",1) -> M | BM11: =IF(AND(BH11="M",BI11="M",BJ11="M",BK11="M",BL11="M",D11=""),0,1) -> 0
A12: -87 | B12: =B13-1 -> -87 | C12: =C13-1 -> -87 | T12: =IF(BM12=0,"M",IF(D12="p1",AK12,IF(D12="p2",AL12,IF(D12="A",0,((E12*F12)*G12/0.6)+((H12*I12)*J12/0.6)+((K12*L12)*M12/0.6)+((N12*O12)*P12/0.6)+((Q12*R12)*S12/0.6))))) -> M | U12: =IF(T12=Calculator!T12,"VALID","ERROR") -> ERROR | W12: =IF(U12="VALID",0,IF(U12="ERROR",1,0)) -> 1 | AK12: =IF(AM12=1,AW12,IF(AM12=2,AQ12,IF(AM12=3,AR12,IF(AM12=4,AS12,IF(AM12=5,AT12,IF(AM12=6,AU12,IF(AM12=7,AV12))))))) -> FALSE | AL12: =IF(AN12=1,BE12,IF(AN12=2,AY12,IF(AN12=3,AZ12,IF(AN12=4,BA12,IF(AN12=5,BB12,IF(AN12=6,BC12,IF(AN12=7,BD12))))))) -> FALSE | AM12: =IF(D12="p1",AP12,"no") -> no | AN12: =IF(D12="p2",AP12,"no") -> no | AP12: =WEEKDAY(C12) -> #NUM! | AQ12: =AQ11 -> M | AR12: =AR11 -> M | AS12: =AS11 -> M | AT12: =AT11 -> M | AU12: =AU11 -> M | AV12: =AV11 -> M | AW12: =AW11 -> M | AY12: =AY11 -> 0 | AZ12: =AZ11 -> 0 | BA12: =BA11 -> 0 | BB12: =BB11 -> 0 | BC12: =BC11 -> 0 | BD12: =BD11 -> 0 | BE12: =BE11 -> 0 | BH12: =IF(OR(E12="",F12="",G12=""),"M",1) -> M | BI12: =IF(OR(H12="",I12="",J12=""),"M",1) -> M | BJ12: =IF(OR(K12="",L12="",M12=""),"M",1) -> M | BK12: =IF(OR(N12="",O12="",P12=""),"M",1) -> M | BL12: =IF(OR(Q12="",R12="",S12=""),"M",1) -> M | BM12: =IF(AND(BH12="M",BI12="M",BJ12="M",BK12="M",BL12="M",D12=""),0,1) -> 0
